[ INFO ][ 2022-05-24 08:00:02,485 ][ basehttp ][ 16440 ][ 139721583982336 ] ==> "GET /wait//29 HTTP/1.1" 200 2920
[ INFO ][ 2022-05-24 08:00:54,154 ][ basehttp ][ 16440 ][ 139721583982336 ] ==> "GET /wait//29 HTTP/1.1" 200 2992
[ INFO ][ 2022-05-24 08:00:56,012 ][ basehttp ][ 16440 ][ 139721583982336 ] ==> "GET /wait//29 HTTP/1.1" 200 2992
[ INFO ][ 2022-05-24 08:01:03,579 ][ basehttp ][ 16440 ][ 139721583982336 ] ==> "GET /wait//29 HTTP/1.1" 200 2928
[ INFO ][ 2022-05-24 08:07:15,456 ][ basehttp ][ 16440 ][ 139721583982336 ] ==> "GET /wait//29 HTTP/1.1" 200 2928
[ WARNING ][ 2022-05-24 08:07:17,728 ][ basehttp ][ 16440 ][ 139721583982336 ] ==> "GET /wait//static/website/front/images/bleu.jpg HTTP/1.1" 404 5723
[ INFO ][ 2022-05-24 08:07:19,090 ][ basehttp ][ 16440 ][ 139721583982336 ] ==> "GET /wait//29 HTTP/1.1" 200 2928
[ WARNING ][ 2022-05-24 08:07:19,323 ][ basehttp ][ 16440 ][ 139721583982336 ] ==> "GET /wait//static/website/front/images/bleu.jpg HTTP/1.1" 404 5723
[ INFO ][ 2022-05-24 08:09:08,415 ][ basehttp ][ 16440 ][ 139721583982336 ] ==> "GET /wait//29 HTTP/1.1" 200 2894
[ WARNING ][ 2022-05-24 08:09:09,530 ][ basehttp ][ 16440 ][ 139721583982336 ] ==> "GET /wait//static/website/front/images/bleu.jpg HTTP/1.1" 404 5723
[ INFO ][ 2022-05-24 08:09:12,386 ][ basehttp ][ 16440 ][ 139721592375040 ] ==> "GET /wait//29 HTTP/1.1" 200 2894
[ WARNING ][ 2022-05-24 08:09:12,753 ][ basehttp ][ 16440 ][ 139721592375040 ] ==> "GET /wait//static/website/front/images/bleu.jpg HTTP/1.1" 404 5723
[ INFO ][ 2022-05-24 08:09:37,156 ][ basehttp ][ 16440 ][ 139721592375040 ] ==> "GET /wait//29 HTTP/1.1" 200 2844
[ WARNING ][ 2022-05-24 08:09:38,268 ][ basehttp ][ 16440 ][ 139721592375040 ] ==> "GET /wait//static/website/front/images/bleu.jpg HTTP/1.1" 404 5723
[ INFO ][ 2022-05-24 08:09:50,759 ][ basehttp ][ 16440 ][ 139721592375040 ] ==> "GET /wait//29 HTTP/1.1" 200 2856
[ WARNING ][ 2022-05-24 08:09:50,962 ][ basehttp ][ 16440 ][ 139721592375040 ] ==> "GET /wait//static/website/front/images/bleu.jpg HTTP/1.1" 404 5723
[ INFO ][ 2022-05-24 08:10:08,267 ][ basehttp ][ 16440 ][ 139721592375040 ] ==> "GET /wait//29 HTTP/1.1" 200 2856
[ WARNING ][ 2022-05-24 08:10:09,808 ][ basehttp ][ 16440 ][ 139721592375040 ] ==> "GET /wait//static/website/front/images/bleu.jpg HTTP/1.1" 404 5723
[ INFO ][ 2022-05-24 08:10:18,738 ][ basehttp ][ 16440 ][ 139721592375040 ] ==> "GET /wait//29 HTTP/1.1" 200 2856
[ WARNING ][ 2022-05-24 08:10:19,305 ][ basehttp ][ 16440 ][ 139721592375040 ] ==> "GET /wait//static/website/front/images/bleu.jpg HTTP/1.1" 404 5723
[ INFO ][ 2022-05-24 08:10:39,896 ][ basehttp ][ 16440 ][ 139721592375040 ] ==> "GET /wait//29 HTTP/1.1" 200 2850
[ WARNING ][ 2022-05-24 08:10:40,095 ][ basehttp ][ 16440 ][ 139721592375040 ] ==> "GET /wait//static/website/front/images/bleu.jpg HTTP/1.1" 404 5723
[ INFO ][ 2022-05-24 08:11:30,950 ][ basehttp ][ 16440 ][ 139721592375040 ] ==> "GET /wait//29 HTTP/1.1" 200 2856
[ WARNING ][ 2022-05-24 08:11:31,177 ][ basehttp ][ 16440 ][ 139721592375040 ] ==> "GET /wait//static/website/front/images/bleu.jpg HTTP/1.1" 404 5723
[ INFO ][ 2022-05-24 08:11:57,577 ][ basehttp ][ 16440 ][ 139721592375040 ] ==> "GET /wait//29 HTTP/1.1" 200 2864
[ WARNING ][ 2022-05-24 08:11:57,797 ][ basehttp ][ 16440 ][ 139721592375040 ] ==> "GET /wait//static/website/front/images/bleu.jpg HTTP/1.1" 404 5723
[ INFO ][ 2022-05-24 08:11:59,723 ][ basehttp ][ 16440 ][ 139721592375040 ] ==> "GET /wait//29 HTTP/1.1" 200 2864
[ WARNING ][ 2022-05-24 08:12:00,238 ][ basehttp ][ 16440 ][ 139721592375040 ] ==> "GET /wait//static/website/front/images/bleu.jpg HTTP/1.1" 404 5723
[ INFO ][ 2022-05-24 08:12:15,250 ][ basehttp ][ 16440 ][ 139721592375040 ] ==> "GET /wait//29 HTTP/1.1" 200 2873
[ WARNING ][ 2022-05-24 08:12:15,471 ][ basehttp ][ 16440 ][ 139721592375040 ] ==> "GET /wait//static/website/front/images/bleu.jpg HTTP/1.1" 404 5723
[ INFO ][ 2022-05-24 08:12:17,297 ][ basehttp ][ 16440 ][ 139721592375040 ] ==> "GET /wait//29 HTTP/1.1" 200 2873
[ WARNING ][ 2022-05-24 08:12:17,442 ][ basehttp ][ 16440 ][ 139721592375040 ] ==> "GET /wait//static/website/front/images/bleu.jpg HTTP/1.1" 404 5723
[ INFO ][ 2022-05-24 08:12:27,554 ][ basehttp ][ 16440 ][ 139721592375040 ] ==> "GET /wait//29 HTTP/1.1" 200 2873
[ WARNING ][ 2022-05-24 08:12:27,726 ][ basehttp ][ 16440 ][ 139721592375040 ] ==> "GET /wait//static/website/front/images/bleu.jpg HTTP/1.1" 404 5723
[ INFO ][ 2022-05-24 08:12:45,014 ][ basehttp ][ 16440 ][ 139721592375040 ] ==> "GET /wait//29 HTTP/1.1" 200 2866
[ WARNING ][ 2022-05-24 08:12:45,172 ][ basehttp ][ 16440 ][ 139721592375040 ] ==> "GET /wait//website/front/images/bleu.jpg HTTP/1.1" 404 5702
[ INFO ][ 2022-05-24 08:20:56,693 ][ basehttp ][ 16440 ][ 139721592375040 ] ==> "GET /wait//29 HTTP/1.1" 200 2867
[ WARNING ][ 2022-05-24 08:20:58,467 ][ basehttp ][ 16440 ][ 139721592375040 ] ==> "GET /wait//website/front/images/bleu.jpg HTTP/1.1" 404 5702
[ INFO ][ 2022-05-24 08:23:18,930 ][ basehttp ][ 16440 ][ 139721592375040 ] ==> "GET /wait//29 HTTP/1.1" 200 2854
[ WARNING ][ 2022-05-24 08:23:20,513 ][ basehttp ][ 16440 ][ 139721592375040 ] ==> "GET /static/bleu.jpg HTTP/1.1" 404 1751
[ INFO ][ 2022-05-24 08:23:36,196 ][ basehttp ][ 16440 ][ 139721573230336 ] ==> "GET /wait//29 HTTP/1.1" 200 2868
[ WARNING ][ 2022-05-24 08:23:36,377 ][ basehttp ][ 16440 ][ 139721573230336 ] ==> "GET /static/website/front/bleu.jpg HTTP/1.1" 404 1793
[ INFO ][ 2022-05-24 08:23:38,138 ][ basehttp ][ 16440 ][ 139721592375040 ] ==> "GET /wait//29 HTTP/1.1" 200 2868
[ WARNING ][ 2022-05-24 08:23:38,210 ][ basehttp ][ 16440 ][ 139721592375040 ] ==> "GET /static/website/front/bleu.jpg HTTP/1.1" 404 1793
[ INFO ][ 2022-05-24 08:23:40,681 ][ basehttp ][ 16440 ][ 139721573230336 ] ==> "GET /wait//29 HTTP/1.1" 200 2868
[ WARNING ][ 2022-05-24 08:23:40,838 ][ basehttp ][ 16440 ][ 139721573230336 ] ==> "GET /static/website/front/bleu.jpg HTTP/1.1" 404 1793
[ INFO ][ 2022-05-24 08:26:36,306 ][ basehttp ][ 16440 ][ 139721592375040 ] ==> "GET /wait//29 HTTP/1.1" 200 2868
[ WARNING ][ 2022-05-24 08:26:36,433 ][ basehttp ][ 16440 ][ 139721592375040 ] ==> "GET /static/website/front/bleu.jpg HTTP/1.1" 404 1793
[ INFO ][ 2022-05-24 08:28:09,191 ][ basehttp ][ 16440 ][ 139721592375040 ] ==> "GET /wait//29 HTTP/1.1" 200 2874
[ WARNING ][ 2022-05-24 08:28:09,310 ][ basehttp ][ 16440 ][ 139721592375040 ] ==> "GET /static/website/front/bleu.jpg HTTP/1.1" 404 1793
[ INFO ][ 2022-05-24 08:28:18,780 ][ basehttp ][ 16440 ][ 139721573230336 ] ==> "GET /wait//29 HTTP/1.1" 200 2868
[ WARNING ][ 2022-05-24 08:28:18,884 ][ basehttp ][ 16440 ][ 139721573230336 ] ==> "GET /static/website/front/bleu.jpg HTTP/1.1" 404 1793
[ INFO ][ 2022-05-24 08:28:50,567 ][ basehttp ][ 16440 ][ 139721592375040 ] ==> "GET /wait//29 HTTP/1.1" 200 2875
[ WARNING ][ 2022-05-24 08:28:50,628 ][ basehttp ][ 16440 ][ 139721592375040 ] ==> "GET /static/website/front/bleu.jpg HTTP/1.1" 404 1793
[ INFO ][ 2022-05-24 08:29:08,246 ][ basehttp ][ 16440 ][ 139721573230336 ] ==> "GET /wait//29 HTTP/1.1" 200 2875
[ WARNING ][ 2022-05-24 08:29:08,309 ][ basehttp ][ 16440 ][ 139721573230336 ] ==> "GET /static/website/front/bleu.jpg HTTP/1.1" 404 1793
[ INFO ][ 2022-05-24 08:29:10,702 ][ basehttp ][ 16440 ][ 139721592375040 ] ==> "GET /wait//29 HTTP/1.1" 200 2875
[ WARNING ][ 2022-05-24 08:29:10,767 ][ basehttp ][ 16440 ][ 139721592375040 ] ==> "GET /static/website/front/bleu.jpg HTTP/1.1" 404 1793
[ INFO ][ 2022-05-24 08:29:14,607 ][ basehttp ][ 16440 ][ 139721573230336 ] ==> "GET /wait//29 HTTP/1.1" 200 2875
[ WARNING ][ 2022-05-24 08:29:14,704 ][ basehttp ][ 16440 ][ 139721573230336 ] ==> "GET /static/website/front/bleu.jpg HTTP/1.1" 404 1793
[ INFO ][ 2022-05-24 08:29:16,857 ][ basehttp ][ 16440 ][ 139721592375040 ] ==> "GET /wait//29 HTTP/1.1" 200 2875
[ WARNING ][ 2022-05-24 08:29:16,916 ][ basehttp ][ 16440 ][ 139721592375040 ] ==> "GET /static/website/front/bleu.jpg HTTP/1.1" 404 1793
[ INFO ][ 2022-05-24 08:31:17,784 ][ basehttp ][ 16440 ][ 139721573230336 ] ==> "GET / HTTP/1.1" 200 8390
[ WARNING ][ 2022-05-24 08:31:18,029 ][ basehttp ][ 16440 ][ 139721573230336 ] ==> "GET /static/fonts.googleapis.com/css%3Ffamily%3DAsap%3A400%2C400i%2C500%2C500i%2C700%2C700i HTTP/1.1" 404 1920
[ WARNING ][ 2022-05-24 08:31:21,365 ][ basehttp ][ 16440 ][ 139721592375040 ] ==> "GET /website/front/js/main.js HTTP/1.1" 404 4451
[ INFO ][ 2022-05-24 08:31:23,211 ][ basehttp ][ 16440 ][ 139721573230336 ] ==> "GET / HTTP/1.1" 200 8390
[ WARNING ][ 2022-05-24 08:31:23,233 ][ basehttp ][ 16440 ][ 139721573230336 ] ==> "GET /static/fonts.googleapis.com/css%3Ffamily%3DAsap%3A400%2C400i%2C500%2C500i%2C700%2C700i HTTP/1.1" 404 1920
[ WARNING ][ 2022-05-24 08:31:25,443 ][ basehttp ][ 16440 ][ 139721592375040 ] ==> "GET /website/front/js/main.js HTTP/1.1" 404 4451
[ INFO ][ 2022-05-24 08:31:46,442 ][ basehttp ][ 16440 ][ 139721592375040 ] ==> "GET /ajax/load-lieu_depart/?compagnie_id=1 HTTP/1.1" 200 190
[ INFO ][ 2022-05-24 08:31:46,564 ][ basehttp ][ 16440 ][ 139721573230336 ] ==> "GET /ajax/load-destination/?compagnie_id=1 HTTP/1.1" 200 187
[ INFO ][ 2022-05-24 08:31:58,228 ][ basehttp ][ 16440 ][ 139721573230336 ] ==> "POST / HTTP/1.1" 302 0
[ INFO ][ 2022-05-24 08:31:58,343 ][ basehttp ][ 16440 ][ 139721573230336 ] ==> "GET /wait//30 HTTP/1.1" 200 2882
[ WARNING ][ 2022-05-24 08:31:58,458 ][ basehttp ][ 16440 ][ 139721573230336 ] ==> "GET /static/website/front/bleu.jpg HTTP/1.1" 404 1793
[ INFO ][ 2022-05-24 08:32:06,271 ][ basehttp ][ 16440 ][ 139721592375040 ] ==> "GET /wait//29 HTTP/1.1" 200 2875
[ WARNING ][ 2022-05-24 08:32:06,383 ][ basehttp ][ 16440 ][ 139721592375040 ] ==> "GET /static/website/front/bleu.jpg HTTP/1.1" 404 1793
[ INFO ][ 2022-05-24 08:32:09,016 ][ basehttp ][ 16440 ][ 139721573230336 ] ==> "GET /wait//29 HTTP/1.1" 200 2875
[ WARNING ][ 2022-05-24 08:32:09,077 ][ basehttp ][ 16440 ][ 139721573230336 ] ==> "GET /static/website/front/bleu.jpg HTTP/1.1" 404 1793
[ INFO ][ 2022-05-24 08:32:10,079 ][ basehttp ][ 16440 ][ 139721592375040 ] ==> "GET /wait//29 HTTP/1.1" 200 2875
[ WARNING ][ 2022-05-24 08:32:10,139 ][ basehttp ][ 16440 ][ 139721592375040 ] ==> "GET /static/website/front/bleu.jpg HTTP/1.1" 404 1793
[ INFO ][ 2022-05-24 08:32:12,628 ][ basehttp ][ 16440 ][ 139721573230336 ] ==> "GET /wait//30 HTTP/1.1" 200 2882
[ WARNING ][ 2022-05-24 08:32:12,685 ][ basehttp ][ 16440 ][ 139721573230336 ] ==> "GET /static/website/front/bleu.jpg HTTP/1.1" 404 1793
[ INFO ][ 2022-05-24 08:32:59,502 ][ basehttp ][ 16440 ][ 139721592375040 ] ==> "GET /wait//30 HTTP/1.1" 200 2656
[ WARNING ][ 2022-05-24 08:32:59,584 ][ basehttp ][ 16440 ][ 139721592375040 ] ==> "GET /static/website/front/bleu.jpg HTTP/1.1" 404 1793
[ INFO ][ 2022-05-24 08:33:18,056 ][ basehttp ][ 16440 ][ 139721573230336 ] ==> "GET /wait//30 HTTP/1.1" 200 2661
[ WARNING ][ 2022-05-24 08:33:18,169 ][ basehttp ][ 16440 ][ 139721573230336 ] ==> "GET /static/website/front/bleu.jpg HTTP/1.1" 404 1793
[ INFO ][ 2022-05-24 08:34:11,256 ][ basehttp ][ 16440 ][ 139721592375040 ] ==> "GET /wait//30 HTTP/1.1" 200 2715
[ WARNING ][ 2022-05-24 08:34:11,315 ][ basehttp ][ 16440 ][ 139721592375040 ] ==> "GET /static/website/front/bleu.jpg HTTP/1.1" 404 1793
[ INFO ][ 2022-05-24 08:34:14,931 ][ basehttp ][ 16440 ][ 139721573230336 ] ==> "GET /wait//30 HTTP/1.1" 200 2715
[ WARNING ][ 2022-05-24 08:34:14,987 ][ basehttp ][ 16440 ][ 139721573230336 ] ==> "GET /static/website/front/bleu.jpg HTTP/1.1" 404 1793
[ INFO ][ 2022-05-24 08:34:15,697 ][ basehttp ][ 16440 ][ 139721592375040 ] ==> "GET /wait//30 HTTP/1.1" 200 2715
[ WARNING ][ 2022-05-24 08:34:15,811 ][ basehttp ][ 16440 ][ 139721592375040 ] ==> "GET /static/website/front/bleu.jpg HTTP/1.1" 404 1793
[ INFO ][ 2022-05-24 08:34:16,611 ][ basehttp ][ 16440 ][ 139721573230336 ] ==> "GET /wait//30 HTTP/1.1" 200 2715
[ WARNING ][ 2022-05-24 08:34:16,704 ][ basehttp ][ 16440 ][ 139721573230336 ] ==> "GET /static/website/front/bleu.jpg HTTP/1.1" 404 1793
[ INFO ][ 2022-05-24 08:34:18,610 ][ basehttp ][ 16440 ][ 139721592375040 ] ==> "GET /wait//30 HTTP/1.1" 200 2715
[ WARNING ][ 2022-05-24 08:34:18,659 ][ basehttp ][ 16440 ][ 139721592375040 ] ==> "GET /static/website/front/bleu.jpg HTTP/1.1" 404 1793
[ INFO ][ 2022-05-24 08:34:22,141 ][ basehttp ][ 16440 ][ 139721573230336 ] ==> "GET /wait//30 HTTP/1.1" 200 2715
[ WARNING ][ 2022-05-24 08:34:22,262 ][ basehttp ][ 16440 ][ 139721573230336 ] ==> "GET /static/website/front/bleu.jpg HTTP/1.1" 404 1793
[ INFO ][ 2022-05-24 08:34:22,702 ][ basehttp ][ 16440 ][ 139721592375040 ] ==> "GET /wait//30 HTTP/1.1" 200 2715
[ WARNING ][ 2022-05-24 08:34:22,812 ][ basehttp ][ 16440 ][ 139721592375040 ] ==> "GET /static/website/front/bleu.jpg HTTP/1.1" 404 1793
[ INFO ][ 2022-05-24 08:34:22,922 ][ basehttp ][ 16440 ][ 139721573230336 ] ==> "GET /wait//30 HTTP/1.1" 200 2715
[ WARNING ][ 2022-05-24 08:34:23,050 ][ basehttp ][ 16440 ][ 139721592375040 ] ==> "GET /static/website/front/bleu.jpg HTTP/1.1" 404 1793
[ INFO ][ 2022-05-24 08:34:23,141 ][ basehttp ][ 16440 ][ 139721573230336 ] ==> "GET /wait//30 HTTP/1.1" 200 2715
[ WARNING ][ 2022-05-24 08:34:23,179 ][ basehttp ][ 16440 ][ 139721573230336 ] ==> "GET /static/website/front/bleu.jpg HTTP/1.1" 404 1793
[ INFO ][ 2022-05-24 08:34:43,764 ][ basehttp ][ 16440 ][ 139721573230336 ] ==> "GET /wait//30 HTTP/1.1" 200 2661
[ WARNING ][ 2022-05-24 08:34:43,880 ][ basehttp ][ 16440 ][ 139721573230336 ] ==> "GET /static/website/front/bleu.jpg HTTP/1.1" 404 1793
[ INFO ][ 2022-05-24 08:36:58,432 ][ basehttp ][ 16440 ][ 139721592375040 ] ==> "GET /wait//30 HTTP/1.1" 200 2684
[ WARNING ][ 2022-05-24 08:36:58,531 ][ basehttp ][ 16440 ][ 139721592375040 ] ==> "GET /static/website/front/bleu.jpg HTTP/1.1" 404 1793
[ INFO ][ 2022-05-24 08:37:01,867 ][ basehttp ][ 16440 ][ 139721592375040 ] ==> "GET /wait//30 HTTP/1.1" 200 2684
[ WARNING ][ 2022-05-24 08:37:01,926 ][ basehttp ][ 16440 ][ 139721592375040 ] ==> "GET /static/website/front/bleu.jpg HTTP/1.1" 404 1793
[ INFO ][ 2022-05-24 08:37:15,983 ][ basehttp ][ 16440 ][ 139721583982336 ] ==> "GET /wait//30 HTTP/1.1" 200 2661
[ WARNING ][ 2022-05-24 08:37:16,056 ][ basehttp ][ 16440 ][ 139721583982336 ] ==> "GET /static/website/front/bleu.jpg HTTP/1.1" 404 1793
[ INFO ][ 2022-05-24 08:44:45,319 ][ basehttp ][ 16440 ][ 139721592375040 ] ==> "GET /wait//30 HTTP/1.1" 200 2655
[ WARNING ][ 2022-05-24 08:44:45,418 ][ basehttp ][ 16440 ][ 139721592375040 ] ==> "GET /static/website/bleu.jpg HTTP/1.1" 404 1775
[ INFO ][ 2022-05-24 08:45:33,104 ][ basehttp ][ 16440 ][ 139721583982336 ] ==> "GET /wait//30 HTTP/1.1" 200 2640
[ WARNING ][ 2022-05-24 08:45:34,367 ][ basehttp ][ 16440 ][ 139721583982336 ] ==> "GET /bleu.jpg HTTP/1.1" 404 4403
[ INFO ][ 2022-05-24 08:45:44,705 ][ basehttp ][ 16440 ][ 139721583982336 ] ==> "GET /wait//30 HTTP/1.1" 200 2639
[ ERROR ][ 2022-05-24 08:45:45,495 ][ log ][ 16440 ][ 139721583982336 ] ==> Internal Server Error: /wait//bleu.jpg
Traceback (most recent call last):
  File "/home/ymane/.local/lib/python3.8/site-packages/django/db/models/fields/__init__.py", line 1772, in get_prep_value
    return int(value)
ValueError: invalid literal for int() with base 10: 'bleu.jpg'

The above exception was the direct cause of the following exception:

Traceback (most recent call last):
  File "/home/ymane/.local/lib/python3.8/site-packages/django/core/handlers/exception.py", line 34, in inner
    response = get_response(request)
  File "/home/ymane/.local/lib/python3.8/site-packages/django/core/handlers/base.py", line 115, in _get_response
    response = self.process_exception_by_middleware(e, request)
  File "/home/ymane/.local/lib/python3.8/site-packages/django/core/handlers/base.py", line 113, in _get_response
    response = wrapped_callback(request, *callback_args, **callback_kwargs)
  File "/home/ymane/Téléchargements/essaie/website/views/waiting_page.py", line 17, in waiting_page
    voyage=Voyage.objects.get(id=last_id)
  File "/home/ymane/.local/lib/python3.8/site-packages/django/db/models/manager.py", line 82, in manager_method
    return getattr(self.get_queryset(), name)(*args, **kwargs)
  File "/home/ymane/.local/lib/python3.8/site-packages/django/db/models/query.py", line 404, in get
    clone = self._chain() if self.query.combinator else self.filter(*args, **kwargs)
  File "/home/ymane/.local/lib/python3.8/site-packages/django/db/models/query.py", line 904, in filter
    return self._filter_or_exclude(False, *args, **kwargs)
  File "/home/ymane/.local/lib/python3.8/site-packages/django/db/models/query.py", line 923, in _filter_or_exclude
    clone.query.add_q(Q(*args, **kwargs))
  File "/home/ymane/.local/lib/python3.8/site-packages/django/db/models/sql/query.py", line 1354, in add_q
    clause, _ = self._add_q(q_object, self.used_aliases)
  File "/home/ymane/.local/lib/python3.8/site-packages/django/db/models/sql/query.py", line 1381, in _add_q
    child_clause, needed_inner = self.build_filter(
  File "/home/ymane/.local/lib/python3.8/site-packages/django/db/models/sql/query.py", line 1315, in build_filter
    condition = self.build_lookup(lookups, col, value)
  File "/home/ymane/.local/lib/python3.8/site-packages/django/db/models/sql/query.py", line 1169, in build_lookup
    lookup = lookup_class(lhs, rhs)
  File "/home/ymane/.local/lib/python3.8/site-packages/django/db/models/lookups.py", line 22, in __init__
    self.rhs = self.get_prep_lookup()
  File "/home/ymane/.local/lib/python3.8/site-packages/django/db/models/lookups.py", line 72, in get_prep_lookup
    return self.lhs.output_field.get_prep_value(self.rhs)
  File "/home/ymane/.local/lib/python3.8/site-packages/django/db/models/fields/__init__.py", line 1774, in get_prep_value
    raise e.__class__(
ValueError: Field 'id' expected a number but got 'bleu.jpg'.
[ ERROR ][ 2022-05-24 08:45:45,673 ][ basehttp ][ 16440 ][ 139721583982336 ] ==> "GET /wait//bleu.jpg HTTP/1.1" 500 148783
[ INFO ][ 2022-05-24 08:45:48,260 ][ basehttp ][ 16440 ][ 139721583982336 ] ==> "GET /wait//30 HTTP/1.1" 200 2639
[ ERROR ][ 2022-05-24 08:45:48,383 ][ log ][ 16440 ][ 139721583982336 ] ==> Internal Server Error: /wait//bleu.jpg
Traceback (most recent call last):
  File "/home/ymane/.local/lib/python3.8/site-packages/django/db/models/fields/__init__.py", line 1772, in get_prep_value
    return int(value)
ValueError: invalid literal for int() with base 10: 'bleu.jpg'

The above exception was the direct cause of the following exception:

Traceback (most recent call last):
  File "/home/ymane/.local/lib/python3.8/site-packages/django/core/handlers/exception.py", line 34, in inner
    response = get_response(request)
  File "/home/ymane/.local/lib/python3.8/site-packages/django/core/handlers/base.py", line 115, in _get_response
    response = self.process_exception_by_middleware(e, request)
  File "/home/ymane/.local/lib/python3.8/site-packages/django/core/handlers/base.py", line 113, in _get_response
    response = wrapped_callback(request, *callback_args, **callback_kwargs)
  File "/home/ymane/Téléchargements/essaie/website/views/waiting_page.py", line 17, in waiting_page
    voyage=Voyage.objects.get(id=last_id)
  File "/home/ymane/.local/lib/python3.8/site-packages/django/db/models/manager.py", line 82, in manager_method
    return getattr(self.get_queryset(), name)(*args, **kwargs)
  File "/home/ymane/.local/lib/python3.8/site-packages/django/db/models/query.py", line 404, in get
    clone = self._chain() if self.query.combinator else self.filter(*args, **kwargs)
  File "/home/ymane/.local/lib/python3.8/site-packages/django/db/models/query.py", line 904, in filter
    return self._filter_or_exclude(False, *args, **kwargs)
  File "/home/ymane/.local/lib/python3.8/site-packages/django/db/models/query.py", line 923, in _filter_or_exclude
    clone.query.add_q(Q(*args, **kwargs))
  File "/home/ymane/.local/lib/python3.8/site-packages/django/db/models/sql/query.py", line 1354, in add_q
    clause, _ = self._add_q(q_object, self.used_aliases)
  File "/home/ymane/.local/lib/python3.8/site-packages/django/db/models/sql/query.py", line 1381, in _add_q
    child_clause, needed_inner = self.build_filter(
  File "/home/ymane/.local/lib/python3.8/site-packages/django/db/models/sql/query.py", line 1315, in build_filter
    condition = self.build_lookup(lookups, col, value)
  File "/home/ymane/.local/lib/python3.8/site-packages/django/db/models/sql/query.py", line 1169, in build_lookup
    lookup = lookup_class(lhs, rhs)
  File "/home/ymane/.local/lib/python3.8/site-packages/django/db/models/lookups.py", line 22, in __init__
    self.rhs = self.get_prep_lookup()
  File "/home/ymane/.local/lib/python3.8/site-packages/django/db/models/lookups.py", line 72, in get_prep_lookup
    return self.lhs.output_field.get_prep_value(self.rhs)
  File "/home/ymane/.local/lib/python3.8/site-packages/django/db/models/fields/__init__.py", line 1774, in get_prep_value
    raise e.__class__(
ValueError: Field 'id' expected a number but got 'bleu.jpg'.
[ ERROR ][ 2022-05-24 08:45:50,231 ][ basehttp ][ 16440 ][ 139721583982336 ] ==> "GET /wait//bleu.jpg HTTP/1.1" 500 148783
[ INFO ][ 2022-05-24 08:51:49,710 ][ basehttp ][ 16440 ][ 139721583982336 ] ==> "GET /wait//30 HTTP/1.1" 200 2659
[ INFO ][ 2022-05-24 08:51:50,570 ][ basehttp ][ 16440 ][ 139721583982336 ] ==> "GET /wait//30 HTTP/1.1" 200 2659
[ INFO ][ 2022-05-24 08:53:43,285 ][ basehttp ][ 16440 ][ 139721583982336 ] ==> "GET / HTTP/1.1" 200 8390
[ WARNING ][ 2022-05-24 08:53:43,349 ][ basehttp ][ 16440 ][ 139721583982336 ] ==> "GET /static/fonts.googleapis.com/css%3Ffamily%3DAsap%3A400%2C400i%2C500%2C500i%2C700%2C700i HTTP/1.1" 404 1920
[ WARNING ][ 2022-05-24 08:53:43,701 ][ basehttp ][ 16440 ][ 139721592375040 ] ==> "GET /website/front/js/main.js HTTP/1.1" 404 4451
[ INFO ][ 2022-05-24 08:59:04,843 ][ basehttp ][ 16440 ][ 139721583982336 ] ==> "GET /wait//30 HTTP/1.1" 200 2661
[ WARNING ][ 2022-05-24 08:59:04,955 ][ basehttp ][ 16440 ][ 139721583982336 ] ==> "GET /static/website/front/bleu.jpg HTTP/1.1" 404 1793
[ INFO ][ 2022-05-24 09:30:48,179 ][ basehttp ][ 16440 ][ 139721592375040 ] ==> "GET /wait//30 HTTP/1.1" 200 2661
[ WARNING ][ 2022-05-24 09:30:48,783 ][ basehttp ][ 16440 ][ 139721592375040 ] ==> "GET /static/website/front/bleu.jpg HTTP/1.1" 404 1793
[ INFO ][ 2022-05-24 09:31:05,289 ][ basehttp ][ 16440 ][ 139721583982336 ] ==> "GET / HTTP/1.1" 200 8390
[ WARNING ][ 2022-05-24 09:31:05,615 ][ basehttp ][ 16440 ][ 139721583982336 ] ==> "GET /static/fonts.googleapis.com/css%3Ffamily%3DAsap%3A400%2C400i%2C500%2C500i%2C700%2C700i HTTP/1.1" 404 1920
[ WARNING ][ 2022-05-24 09:31:05,890 ][ basehttp ][ 16440 ][ 139721592375040 ] ==> "GET /website/front/js/main.js HTTP/1.1" 404 4451
[ INFO ][ 2022-05-24 09:31:24,018 ][ basehttp ][ 16440 ][ 139721583982336 ] ==> "GET /ajax/load-destination/?compagnie_id=3 HTTP/1.1" 200 186
[ INFO ][ 2022-05-24 09:31:24,129 ][ basehttp ][ 16440 ][ 139721592375040 ] ==> "GET /ajax/load-lieu_depart/?compagnie_id=3 HTTP/1.1" 200 189
[ INFO ][ 2022-05-24 09:31:36,764 ][ basehttp ][ 16440 ][ 139721592375040 ] ==> "POST / HTTP/1.1" 302 0
[ ERROR ][ 2022-05-24 09:31:37,701 ][ log ][ 16440 ][ 139721592375040 ] ==> Internal Server Error: /wait//31
Traceback (most recent call last):
  File "/home/ymane/.local/lib/python3.8/site-packages/django/core/handlers/exception.py", line 34, in inner
    response = get_response(request)
  File "/home/ymane/.local/lib/python3.8/site-packages/django/core/handlers/base.py", line 115, in _get_response
    response = self.process_exception_by_middleware(e, request)
  File "/home/ymane/.local/lib/python3.8/site-packages/django/core/handlers/base.py", line 113, in _get_response
    response = wrapped_callback(request, *callback_args, **callback_kwargs)
  File "/home/ymane/Téléchargements/essaie/website/views/waiting_page.py", line 20, in waiting_page
    montant=Montant.objects.get(depart=depart,destination=destination)
  File "/home/ymane/.local/lib/python3.8/site-packages/django/db/models/manager.py", line 82, in manager_method
    return getattr(self.get_queryset(), name)(*args, **kwargs)
  File "/home/ymane/.local/lib/python3.8/site-packages/django/db/models/query.py", line 415, in get
    raise self.model.DoesNotExist(
start_form.models.Montant.DoesNotExist: Montant matching query does not exist.
[ ERROR ][ 2022-05-24 09:31:37,881 ][ basehttp ][ 16440 ][ 139721592375040 ] ==> "GET /wait//31 HTTP/1.1" 500 100124
[ INFO ][ 2022-05-24 09:31:49,284 ][ basehttp ][ 16440 ][ 139721592375040 ] ==> "POST / HTTP/1.1" 302 0
[ ERROR ][ 2022-05-24 09:31:49,465 ][ log ][ 16440 ][ 139721592375040 ] ==> Internal Server Error: /wait//32
Traceback (most recent call last):
  File "/home/ymane/.local/lib/python3.8/site-packages/django/core/handlers/exception.py", line 34, in inner
    response = get_response(request)
  File "/home/ymane/.local/lib/python3.8/site-packages/django/core/handlers/base.py", line 115, in _get_response
    response = self.process_exception_by_middleware(e, request)
  File "/home/ymane/.local/lib/python3.8/site-packages/django/core/handlers/base.py", line 113, in _get_response
    response = wrapped_callback(request, *callback_args, **callback_kwargs)
  File "/home/ymane/Téléchargements/essaie/website/views/waiting_page.py", line 20, in waiting_page
    montant=Montant.objects.get(depart=depart,destination=destination)
  File "/home/ymane/.local/lib/python3.8/site-packages/django/db/models/manager.py", line 82, in manager_method
    return getattr(self.get_queryset(), name)(*args, **kwargs)
  File "/home/ymane/.local/lib/python3.8/site-packages/django/db/models/query.py", line 415, in get
    raise self.model.DoesNotExist(
start_form.models.Montant.DoesNotExist: Montant matching query does not exist.
[ ERROR ][ 2022-05-24 09:31:49,647 ][ basehttp ][ 16440 ][ 139721592375040 ] ==> "GET /wait//32 HTTP/1.1" 500 100124
[ INFO ][ 2022-05-24 09:31:58,403 ][ basehttp ][ 16440 ][ 139721592375040 ] ==> "POST / HTTP/1.1" 302 0
[ INFO ][ 2022-05-24 09:31:58,620 ][ basehttp ][ 16440 ][ 139721592375040 ] ==> "GET /wait//33 HTTP/1.1" 200 2656
[ WARNING ][ 2022-05-24 09:31:58,948 ][ basehttp ][ 16440 ][ 139721592375040 ] ==> "GET /static/website/front/bleu.jpg HTTP/1.1" 404 1793
[ INFO ][ 2022-05-24 09:37:03,779 ][ basehttp ][ 16440 ][ 139721592375040 ] ==> "GET /wait//33 HTTP/1.1" 200 2655
[ WARNING ][ 2022-05-24 09:37:03,868 ][ basehttp ][ 16440 ][ 139721592375040 ] ==> "GET /static/website/front/bleu.jpg HTTP/1.1" 404 1793
[ INFO ][ 2022-05-24 09:37:06,714 ][ basehttp ][ 16440 ][ 139721573230336 ] ==> "GET /wait//33 HTTP/1.1" 200 2655
[ WARNING ][ 2022-05-24 09:37:06,782 ][ basehttp ][ 16440 ][ 139721573230336 ] ==> "GET /static/website/front/bleu.jpg HTTP/1.1" 404 1793
[ INFO ][ 2022-05-24 09:59:32,483 ][ basehttp ][ 16440 ][ 139721592375040 ] ==> "GET /wait//33 HTTP/1.1" 200 2655
[ WARNING ][ 2022-05-24 09:59:32,580 ][ basehttp ][ 16440 ][ 139721592375040 ] ==> "GET /static/website/front/bleu.jpg HTTP/1.1" 404 1793
[ WARNING ][ 2022-05-24 10:01:30,396 ][ basehttp ][ 16440 ][ 139721573230336 ] ==> "GET /wait//static%20'website/front/bleu.jpg' HTTP/1.1" 404 5740
[ INFO ][ 2022-05-24 10:13:07,323 ][ basehttp ][ 16440 ][ 139721573230336 ] ==> "GET /wait//33 HTTP/1.1" 200 2656
[ WARNING ][ 2022-05-24 10:13:07,447 ][ basehttp ][ 16440 ][ 139721573230336 ] ==> "GET /static/website/front/bleus.jpg HTTP/1.1" 404 1796
[ INFO ][ 2022-05-24 10:13:09,751 ][ basehttp ][ 16440 ][ 139721592375040 ] ==> "GET /wait//33 HTTP/1.1" 200 2656
[ WARNING ][ 2022-05-24 10:13:09,883 ][ basehttp ][ 16440 ][ 139721592375040 ] ==> "GET /static/website/front/bleus.jpg HTTP/1.1" 404 1796
[ INFO ][ 2022-05-24 10:14:49,109 ][ basehttp ][ 16440 ][ 139721573230336 ] ==> "GET /wait//33 HTTP/1.1" 200 2717
[ WARNING ][ 2022-05-24 10:14:49,254 ][ basehttp ][ 16440 ][ 139721592375040 ] ==> "GET /static/website/front/bleus.jpg HTTP/1.1" 404 1796
[ INFO ][ 2022-05-24 10:14:49,260 ][ basehttp ][ 16440 ][ 139721573230336 ] ==> "GET /static/website/front/images/bleus.jpg HTTP/1.1" 200 954287
[ INFO ][ 2022-05-24 10:22:59,462 ][ basehttp ][ 16440 ][ 139721573230336 ] ==> "GET /wait//33 HTTP/1.1" 200 2718
[ INFO ][ 2022-05-24 10:23:00,447 ][ basehttp ][ 16440 ][ 139721592375040 ] ==> "GET /static/website/front/images/bleus.jpg HTTP/1.1" 304 0
[ WARNING ][ 2022-05-24 10:23:00,453 ][ basehttp ][ 16440 ][ 139721573230336 ] ==> "GET /static/website/front/bleus.jpg HTTP/1.1" 404 1796
[ INFO ][ 2022-05-24 10:23:51,434 ][ basehttp ][ 16440 ][ 139721592375040 ] ==> "GET /wait//33 HTTP/1.1" 200 2744
[ WARNING ][ 2022-05-24 10:23:51,493 ][ basehttp ][ 16440 ][ 139721592375040 ] ==> "GET /static/website/front/bleus.jpg HTTP/1.1" 404 1796
[ INFO ][ 2022-05-24 10:23:52,548 ][ basehttp ][ 16440 ][ 139721573230336 ] ==> "GET /wait//33 HTTP/1.1" 200 2744
[ WARNING ][ 2022-05-24 10:23:52,602 ][ basehttp ][ 16440 ][ 139721573230336 ] ==> "GET /static/website/front/bleus.jpg HTTP/1.1" 404 1796
[ INFO ][ 2022-05-24 10:24:18,862 ][ basehttp ][ 16440 ][ 139721592375040 ] ==> "GET /wait//33 HTTP/1.1" 200 2741
[ WARNING ][ 2022-05-24 10:24:18,923 ][ basehttp ][ 16440 ][ 139721592375040 ] ==> "GET /static/website/front/bleus.jpg HTTP/1.1" 404 1796
[ INFO ][ 2022-05-24 10:24:19,547 ][ basehttp ][ 16440 ][ 139721573230336 ] ==> "GET /wait//33 HTTP/1.1" 200 2741
[ WARNING ][ 2022-05-24 10:24:19,605 ][ basehttp ][ 16440 ][ 139721573230336 ] ==> "GET /static/website/front/bleus.jpg HTTP/1.1" 404 1796
[ INFO ][ 2022-05-24 10:25:07,982 ][ basehttp ][ 16440 ][ 139721592375040 ] ==> "GET /wait//33 HTTP/1.1" 200 2745
[ INFO ][ 2022-05-24 10:25:08,066 ][ basehttp ][ 16440 ][ 139721592375040 ] ==> "GET /static/website/front/images/bleus.jpg HTTP/1.1" 304 0
[ WARNING ][ 2022-05-24 10:25:08,473 ][ basehttp ][ 16440 ][ 139721592375040 ] ==> "GET /static/website/front/bleus.jpg HTTP/1.1" 404 1796
[ INFO ][ 2022-05-24 10:25:13,334 ][ basehttp ][ 16440 ][ 139721573230336 ] ==> "GET /wait//33 HTTP/1.1" 200 2745
[ WARNING ][ 2022-05-24 10:25:13,442 ][ basehttp ][ 16440 ][ 139721573230336 ] ==> "GET /static/website/front/bleus.jpg HTTP/1.1" 404 1796
[ INFO ][ 2022-05-24 10:25:13,940 ][ basehttp ][ 16440 ][ 139721592375040 ] ==> "GET /wait//33 HTTP/1.1" 200 2745
[ WARNING ][ 2022-05-24 10:25:14,050 ][ basehttp ][ 16440 ][ 139721592375040 ] ==> "GET /static/website/front/bleus.jpg HTTP/1.1" 404 1796
[ INFO ][ 2022-05-24 10:26:05,912 ][ basehttp ][ 16440 ][ 139721573230336 ] ==> "GET /wait//33 HTTP/1.1" 200 2665
[ WARNING ][ 2022-05-24 10:26:06,030 ][ basehttp ][ 16440 ][ 139721573230336 ] ==> "GET /static/website/front/bleus.jpg HTTP/1.1" 404 1796
[ INFO ][ 2022-05-24 10:27:55,930 ][ basehttp ][ 16440 ][ 139721592375040 ] ==> "GET /wait//33 HTTP/1.1" 200 2665
[ WARNING ][ 2022-05-24 10:27:55,972 ][ basehttp ][ 16440 ][ 139721592375040 ] ==> "GET /static/website/front/bleus.jpg HTTP/1.1" 404 1796
[ INFO ][ 2022-05-24 10:31:56,337 ][ basehttp ][ 16440 ][ 139721573230336 ] ==> "GET /wait//33 HTTP/1.1" 200 2688
[ INFO ][ 2022-05-24 10:34:07,953 ][ basehttp ][ 16440 ][ 139721573230336 ] ==> "GET /wait//33 HTTP/1.1" 200 2663
[ WARNING ][ 2022-05-24 10:34:08,156 ][ basehttp ][ 16440 ][ 139721573230336 ] ==> "GET /static/website/front/bleus.jpg HTTP/1.1" 404 1796
[ INFO ][ 2022-05-24 10:34:19,455 ][ basehttp ][ 16440 ][ 139721592375040 ] ==> "GET /wait//33 HTTP/1.1" 200 2665
[ WARNING ][ 2022-05-24 10:34:19,594 ][ basehttp ][ 16440 ][ 139721592375040 ] ==> "GET /static/website/front/bleus.jpg HTTP/1.1" 404 1796
[ INFO ][ 2022-05-24 10:34:23,767 ][ basehttp ][ 16440 ][ 139721573230336 ] ==> "GET /wait//33 HTTP/1.1" 200 2665
[ WARNING ][ 2022-05-24 10:34:23,840 ][ basehttp ][ 16440 ][ 139721573230336 ] ==> "GET /static/website/front/bleus.jpg HTTP/1.1" 404 1796
[ INFO ][ 2022-05-24 11:15:39,670 ][ basehttp ][ 16440 ][ 139721592375040 ] ==> "GET /wait//33 HTTP/1.1" 200 2665
[ WARNING ][ 2022-05-24 11:15:39,744 ][ basehttp ][ 16440 ][ 139721592375040 ] ==> "GET /static/website/front/bleus.jpg HTTP/1.1" 404 1796
[ INFO ][ 2022-05-24 11:15:48,240 ][ basehttp ][ 16440 ][ 139721573230336 ] ==> "GET /back-office/ HTTP/1.1" 200 2418
[ INFO ][ 2022-05-24 11:15:48,988 ][ basehttp ][ 16440 ][ 139721592375040 ] ==> "GET /static/oauth/js/jquery.min.js HTTP/1.1" 200 86927
[ INFO ][ 2022-05-24 11:15:48,991 ][ basehttp ][ 16440 ][ 139721573230336 ] ==> "GET /static/oauth/css/bootstrap.min.css HTTP/1.1" 200 140938
[ INFO ][ 2022-05-24 11:15:49,283 ][ basehttp ][ 16440 ][ 139721573230336 ] ==> "GET /static/oauth/images/img2.jpg HTTP/1.1" 200 432568
[ INFO ][ 2022-05-24 11:16:12,589 ][ basehttp ][ 16440 ][ 139721573230336 ] ==> "POST /back-office/login/ HTTP/1.1" 302 0
[ INFO ][ 2022-05-24 11:16:17,105 ][ basehttp ][ 16440 ][ 139721573230336 ] ==> "GET /back-office/dashboard HTTP/1.1" 200 167564
[ INFO ][ 2022-05-24 11:16:17,652 ][ basehttp ][ 16440 ][ 139721573230336 ] ==> "GET /static/website/back/js/jquery.min.js HTTP/1.1" 200 84380
[ INFO ][ 2022-05-24 11:16:17,666 ][ basehttp ][ 16440 ][ 139721592375040 ] ==> "GET /static/website/back/css/bootstrap.min.css HTTP/1.1" 200 121168
[ INFO ][ 2022-05-24 11:16:17,673 ][ basehttp ][ 16440 ][ 139721563264768 ] ==> "GET /static/website/back/css/icons.css HTTP/1.1" 200 201989
[ INFO ][ 2022-05-24 11:16:17,685 ][ basehttp ][ 16440 ][ 139721583982336 ] ==> "GET /static/website/back/css/components.css HTTP/1.1" 200 84793
[ INFO ][ 2022-05-24 11:16:18,493 ][ basehttp ][ 16440 ][ 139721563264768 ] ==> "GET /static/website/back/plugins/moment/moment.js HTTP/1.1" 200 139009
[ WARNING ][ 2022-05-24 11:16:19,169 ][ basehttp ][ 16440 ][ 139721563264768 ] ==> "GET /static/website/back/fonts/fontawesome-webfont.woff2%3Fv=4.6.3 HTTP/1.1" 404 1887
[ WARNING ][ 2022-05-24 11:16:19,206 ][ basehttp ][ 16440 ][ 139721592375040 ] ==> "GET /static/website/back/fonts/materialdesignicons-webfont.woff2%3Fv=1.6.50 HTTP/1.1" 404 1914
[ WARNING ][ 2022-05-24 11:16:19,349 ][ basehttp ][ 16440 ][ 139721573230336 ] ==> "GET /static/website/back/fonts/fontawesome-webfont.woff%3Fv=4.6.3 HTTP/1.1" 404 1884
[ WARNING ][ 2022-05-24 11:16:19,525 ][ basehttp ][ 16440 ][ 139721583982336 ] ==> "GET /static/website/back/fonts/materialdesignicons-webfont.woff%3Fv=1.6.50 HTTP/1.1" 404 1911
[ WARNING ][ 2022-05-24 11:16:19,592 ][ basehttp ][ 16440 ][ 139721583982336 ] ==> "GET /static/website/back/fonts/fontawesome-webfont.ttf%3Fv=4.6.3 HTTP/1.1" 404 1881
[ WARNING ][ 2022-05-24 11:16:19,595 ][ basehttp ][ 16440 ][ 139721573230336 ] ==> "GET /static/website/back/fonts/materialdesignicons-webfont.ttf%3Fv=1.6.50 HTTP/1.1" 404 1908
[ INFO ][ 2022-05-24 11:21:53,202 ][ basehttp ][ 16440 ][ 139721573230336 ] ==> "GET /back-office/traitement/1 HTTP/1.1" 200 840
[ INFO ][ 2022-05-24 11:22:02,724 ][ basehttp ][ 16440 ][ 139721573230336 ] ==> "GET /back-office/dashboard HTTP/1.1" 200 167564
[ WARNING ][ 2022-05-24 11:22:03,014 ][ basehttp ][ 16440 ][ 139721583982336 ] ==> "GET /static/website/back/fonts/fontawesome-webfont.woff2%3Fv=4.6.3 HTTP/1.1" 404 1887
[ WARNING ][ 2022-05-24 11:22:03,017 ][ basehttp ][ 16440 ][ 139721573230336 ] ==> "GET /static/website/back/fonts/materialdesignicons-webfont.woff2%3Fv=1.6.50 HTTP/1.1" 404 1914
[ WARNING ][ 2022-05-24 11:22:03,252 ][ basehttp ][ 16440 ][ 139721573230336 ] ==> "GET /static/website/back/fonts/fontawesome-webfont.woff%3Fv=4.6.3 HTTP/1.1" 404 1884
[ WARNING ][ 2022-05-24 11:22:03,258 ][ basehttp ][ 16440 ][ 139721583982336 ] ==> "GET /static/website/back/fonts/materialdesignicons-webfont.woff%3Fv=1.6.50 HTTP/1.1" 404 1911
[ WARNING ][ 2022-05-24 11:22:03,356 ][ basehttp ][ 16440 ][ 139721583982336 ] ==> "GET /static/website/back/fonts/fontawesome-webfont.ttf%3Fv=4.6.3 HTTP/1.1" 404 1881
[ WARNING ][ 2022-05-24 11:22:03,359 ][ basehttp ][ 16440 ][ 139721573230336 ] ==> "GET /static/website/back/fonts/materialdesignicons-webfont.ttf%3Fv=1.6.50 HTTP/1.1" 404 1908
[ INFO ][ 2022-05-24 11:28:50,684 ][ basehttp ][ 16440 ][ 139721573230336 ] ==> "GET /back-office/dashboard HTTP/1.1" 200 167564
[ WARNING ][ 2022-05-24 11:28:51,064 ][ basehttp ][ 16440 ][ 139721573230336 ] ==> "GET /static/website/back/fonts/materialdesignicons-webfont.woff2%3Fv=1.6.50 HTTP/1.1" 404 1914
[ WARNING ][ 2022-05-24 11:28:51,073 ][ basehttp ][ 16440 ][ 139721583982336 ] ==> "GET /static/website/back/fonts/fontawesome-webfont.woff2%3Fv=4.6.3 HTTP/1.1" 404 1887
[ WARNING ][ 2022-05-24 11:28:51,171 ][ basehttp ][ 16440 ][ 139721583982336 ] ==> "GET /static/website/back/fonts/materialdesignicons-webfont.woff%3Fv=1.6.50 HTTP/1.1" 404 1911
[ WARNING ][ 2022-05-24 11:28:51,175 ][ basehttp ][ 16440 ][ 139721573230336 ] ==> "GET /static/website/back/fonts/fontawesome-webfont.woff%3Fv=4.6.3 HTTP/1.1" 404 1884
[ WARNING ][ 2022-05-24 11:28:51,228 ][ basehttp ][ 16440 ][ 139721573230336 ] ==> "GET /static/website/back/fonts/materialdesignicons-webfont.ttf%3Fv=1.6.50 HTTP/1.1" 404 1908
[ WARNING ][ 2022-05-24 11:28:51,229 ][ basehttp ][ 16440 ][ 139721583982336 ] ==> "GET /static/website/back/fonts/fontawesome-webfont.ttf%3Fv=4.6.3 HTTP/1.1" 404 1881
[ INFO ][ 2022-05-24 11:28:59,008 ][ basehttp ][ 16440 ][ 139721583982336 ] ==> "GET /back-office/traitement/5 HTTP/1.1" 200 840
[ INFO ][ 2022-05-24 11:29:03,916 ][ basehttp ][ 16440 ][ 139721583982336 ] ==> "GET /back-office/dashboard HTTP/1.1" 200 167564
[ WARNING ][ 2022-05-24 11:29:04,120 ][ basehttp ][ 16440 ][ 139721573230336 ] ==> "GET /static/website/back/fonts/fontawesome-webfont.woff2%3Fv=4.6.3 HTTP/1.1" 404 1887
[ WARNING ][ 2022-05-24 11:29:04,122 ][ basehttp ][ 16440 ][ 139721583982336 ] ==> "GET /static/website/back/fonts/materialdesignicons-webfont.woff2%3Fv=1.6.50 HTTP/1.1" 404 1914
[ WARNING ][ 2022-05-24 11:29:04,247 ][ basehttp ][ 16440 ][ 139721583982336 ] ==> "GET /static/website/back/fonts/fontawesome-webfont.woff%3Fv=4.6.3 HTTP/1.1" 404 1884
[ WARNING ][ 2022-05-24 11:29:04,255 ][ basehttp ][ 16440 ][ 139721573230336 ] ==> "GET /static/website/back/fonts/materialdesignicons-webfont.woff%3Fv=1.6.50 HTTP/1.1" 404 1911
[ WARNING ][ 2022-05-24 11:29:04,440 ][ basehttp ][ 16440 ][ 139721573230336 ] ==> "GET /static/website/back/fonts/fontawesome-webfont.ttf%3Fv=4.6.3 HTTP/1.1" 404 1881
[ WARNING ][ 2022-05-24 11:29:04,456 ][ basehttp ][ 16440 ][ 139721583982336 ] ==> "GET /static/website/back/fonts/materialdesignicons-webfont.ttf%3Fv=1.6.50 HTTP/1.1" 404 1908
[ INFO ][ 2022-05-24 11:29:06,139 ][ basehttp ][ 16440 ][ 139721583982336 ] ==> "GET /back-office/traitement/1 HTTP/1.1" 200 840
[ INFO ][ 2022-05-24 11:29:09,955 ][ basehttp ][ 16440 ][ 139721583982336 ] ==> "GET /back-office/dashboard HTTP/1.1" 200 167564
[ WARNING ][ 2022-05-24 11:29:10,188 ][ basehttp ][ 16440 ][ 139721573230336 ] ==> "GET /static/website/back/fonts/fontawesome-webfont.woff2%3Fv=4.6.3 HTTP/1.1" 404 1887
[ WARNING ][ 2022-05-24 11:29:10,197 ][ basehttp ][ 16440 ][ 139721583982336 ] ==> "GET /static/website/back/fonts/materialdesignicons-webfont.woff2%3Fv=1.6.50 HTTP/1.1" 404 1914
[ WARNING ][ 2022-05-24 11:29:10,295 ][ basehttp ][ 16440 ][ 139721583982336 ] ==> "GET /static/website/back/fonts/fontawesome-webfont.woff%3Fv=4.6.3 HTTP/1.1" 404 1884
[ WARNING ][ 2022-05-24 11:29:10,301 ][ basehttp ][ 16440 ][ 139721573230336 ] ==> "GET /static/website/back/fonts/materialdesignicons-webfont.woff%3Fv=1.6.50 HTTP/1.1" 404 1911
[ WARNING ][ 2022-05-24 11:29:10,454 ][ basehttp ][ 16440 ][ 139721573230336 ] ==> "GET /static/website/back/fonts/fontawesome-webfont.ttf%3Fv=4.6.3 HTTP/1.1" 404 1881
[ WARNING ][ 2022-05-24 11:29:10,612 ][ basehttp ][ 16440 ][ 139721573230336 ] ==> "GET /static/website/back/fonts/materialdesignicons-webfont.ttf%3Fv=1.6.50 HTTP/1.1" 404 1908
[ INFO ][ 2022-05-24 11:43:12,801 ][ basehttp ][ 16440 ][ 139721573230336 ] ==> "GET /session_security/ping/?idleFor=649&_=1653391750223 HTTP/1.1" 200 3
[ INFO ][ 2022-05-24 11:46:25,895 ][ basehttp ][ 16440 ][ 139721573230336 ] ==> "GET /session_security/ping/?idleFor=163&_=1653391750224 HTTP/1.1" 200 3
[ INFO ][ 2022-05-24 11:51:38,234 ][ basehttp ][ 16440 ][ 139721573230336 ] ==> "GET /wait//33 HTTP/1.1" 200 2665
[ WARNING ][ 2022-05-24 11:51:38,365 ][ basehttp ][ 16440 ][ 139721573230336 ] ==> "GET /static/website/front/bleus.jpg HTTP/1.1" 404 1796
[ INFO ][ 2022-05-24 11:51:39,752 ][ basehttp ][ 16440 ][ 139721583982336 ] ==> "GET /wait//33 HTTP/1.1" 200 2665
[ WARNING ][ 2022-05-24 11:51:39,833 ][ basehttp ][ 16440 ][ 139721583982336 ] ==> "GET /static/website/front/bleus.jpg HTTP/1.1" 404 1796
[ INFO ][ 2022-05-24 11:51:40,942 ][ basehttp ][ 16440 ][ 139721573230336 ] ==> "GET /wait//33 HTTP/1.1" 200 2665
[ WARNING ][ 2022-05-24 11:51:40,997 ][ basehttp ][ 16440 ][ 139721573230336 ] ==> "GET /static/website/front/bleus.jpg HTTP/1.1" 404 1796
[ INFO ][ 2022-05-24 11:51:51,396 ][ basehttp ][ 16440 ][ 139721583982336 ] ==> "GET /wait//33 HTTP/1.1" 200 2665
[ WARNING ][ 2022-05-24 11:51:51,531 ][ basehttp ][ 16440 ][ 139721583982336 ] ==> "GET /static/website/front/bleus.jpg HTTP/1.1" 404 1796
[ INFO ][ 2022-05-24 11:52:40,386 ][ basehttp ][ 16440 ][ 139721573230336 ] ==> "GET /wait//33 HTTP/1.1" 200 2672
[ INFO ][ 2022-05-24 11:52:40,540 ][ basehttp ][ 16440 ][ 139721573230336 ] ==> "GET /static/website/front/images/bleus.jpg HTTP/1.1" 304 0
[ INFO ][ 2022-05-24 11:52:44,229 ][ basehttp ][ 16440 ][ 139721583982336 ] ==> "GET /wait//33 HTTP/1.1" 200 2672
[ INFO ][ 2022-05-24 11:53:02,084 ][ basehttp ][ 16440 ][ 139721583982336 ] ==> "GET /wait//33 HTTP/1.1" 200 2672
[ INFO ][ 2022-05-24 11:53:17,750 ][ basehttp ][ 16440 ][ 139721583982336 ] ==> "GET /wait//33 HTTP/1.1" 200 2667
[ INFO ][ 2022-05-24 11:56:56,313 ][ basehttp ][ 16440 ][ 139721592375040 ] ==> "GET /wait//27 HTTP/1.1" 200 2689
[ INFO ][ 2022-05-24 11:57:22,183 ][ basehttp ][ 16440 ][ 139721592375040 ] ==> "GET /static/website/front/images/bleus.jpg HTTP/1.1" 200 954287
[ INFO ][ 2022-05-24 11:57:44,379 ][ basehttp ][ 16440 ][ 139721583982336 ] ==> "GET /session_security/ping/?idleFor=440&_=1653391750225 HTTP/1.1" 200 3
[ INFO ][ 2022-05-24 12:07:20,228 ][ basehttp ][ 16440 ][ 139721583982336 ] ==> "GET /session_security/ping/?idleFor=476&_=1653391750226 HTTP/1.1" 200 3
[ INFO ][ 2022-05-24 12:13:25,974 ][ basehttp ][ 16440 ][ 139721583982336 ] ==> "GET /session_security/ping/?idleFor=840&_=1653391750227 HTTP/1.1" 200 3
[ INFO ][ 2022-05-24 12:14:07,363 ][ basehttp ][ 16440 ][ 139721583982336 ] ==> "GET /session_security/ping/?idleFor=0&_=1653391750228 HTTP/1.1" 200 1
[ INFO ][ 2022-05-24 12:17:04,346 ][ basehttp ][ 16440 ][ 139721573230336 ] ==> "GET /wait//33 HTTP/1.1" 200 2704
[ INFO ][ 2022-05-24 12:17:14,239 ][ basehttp ][ 16440 ][ 139721573230336 ] ==> "GET /static/website/front/images/bleus.jpg HTTP/1.1" 304 0
[ ERROR ][ 2022-05-24 12:17:14,236 ][ log ][ 16440 ][ 139721583982336 ] ==> Internal Server Error: /wait//33
Traceback (most recent call last):
  File "/home/ymane/.local/lib/python3.8/site-packages/django/db/backends/utils.py", line 86, in _execute
    return self.cursor.execute(sql, params)
  File "/home/ymane/.local/lib/python3.8/site-packages/django/db/backends/sqlite3/base.py", line 396, in execute
    return Database.Cursor.execute(self, query, params)
sqlite3.OperationalError: database is locked

The above exception was the direct cause of the following exception:

Traceback (most recent call last):
  File "/home/ymane/.local/lib/python3.8/site-packages/django/core/handlers/exception.py", line 34, in inner
    response = get_response(request)
  File "/home/ymane/.local/lib/python3.8/site-packages/django/utils/deprecation.py", line 96, in __call__
    response = self.process_response(request, response)
  File "/home/ymane/Téléchargements/essaie/request/middleware.py", line 41, in process_response
    r.from_http_request(request, response)
  File "/home/ymane/Téléchargements/essaie/request/models.py", line 82, in from_http_request
    self.save()
  File "/home/ymane/Téléchargements/essaie/request/models.py", line 120, in save
    super(Request, self).save(*args, **kwargs)
  File "/home/ymane/.local/lib/python3.8/site-packages/django/db/models/base.py", line 745, in save
    self.save_base(using=using, force_insert=force_insert,
  File "/home/ymane/.local/lib/python3.8/site-packages/django/db/models/base.py", line 782, in save_base
    updated = self._save_table(
  File "/home/ymane/.local/lib/python3.8/site-packages/django/db/models/base.py", line 887, in _save_table
    results = self._do_insert(cls._base_manager, using, fields, returning_fields, raw)
  File "/home/ymane/.local/lib/python3.8/site-packages/django/db/models/base.py", line 924, in _do_insert
    return manager._insert(
  File "/home/ymane/.local/lib/python3.8/site-packages/django/db/models/manager.py", line 82, in manager_method
    return getattr(self.get_queryset(), name)(*args, **kwargs)
  File "/home/ymane/.local/lib/python3.8/site-packages/django/db/models/query.py", line 1204, in _insert
    return query.get_compiler(using=using).execute_sql(returning_fields)
  File "/home/ymane/.local/lib/python3.8/site-packages/django/db/models/sql/compiler.py", line 1392, in execute_sql
    cursor.execute(sql, params)
  File "/home/ymane/.local/lib/python3.8/site-packages/django/db/backends/utils.py", line 100, in execute
    return super().execute(sql, params)
  File "/home/ymane/.local/lib/python3.8/site-packages/django/db/backends/utils.py", line 68, in execute
    return self._execute_with_wrappers(sql, params, many=False, executor=self._execute)
  File "/home/ymane/.local/lib/python3.8/site-packages/django/db/backends/utils.py", line 77, in _execute_with_wrappers
    return executor(sql, params, many, context)
  File "/home/ymane/.local/lib/python3.8/site-packages/django/db/backends/utils.py", line 86, in _execute
    return self.cursor.execute(sql, params)
  File "/home/ymane/.local/lib/python3.8/site-packages/django/db/utils.py", line 90, in __exit__
    raise dj_exc_value.with_traceback(traceback) from exc_value
  File "/home/ymane/.local/lib/python3.8/site-packages/django/db/backends/utils.py", line 86, in _execute
    return self.cursor.execute(sql, params)
  File "/home/ymane/.local/lib/python3.8/site-packages/django/db/backends/sqlite3/base.py", line 396, in execute
    return Database.Cursor.execute(self, query, params)
django.db.utils.OperationalError: database is locked
[ INFO ][ 2022-05-24 12:28:10,708 ][ basehttp ][ 16440 ][ 139721573230336 ] ==> "GET /session_security/ping/?idleFor=1&_=1653391750229 HTTP/1.1" 200 1
[ INFO ][ 2022-05-24 12:42:12,081 ][ basehttp ][ 16440 ][ 139721573230336 ] ==> "GET /session_security/ping/?idleFor=781&_=1653391750230 HTTP/1.1" 200 3
[ INFO ][ 2022-05-24 12:43:12,035 ][ basehttp ][ 16440 ][ 139721573230336 ] ==> "GET /session_security/ping/?idleFor=840&_=1653391750231 HTTP/1.1" 200 3
[ INFO ][ 2022-05-24 12:44:14,725 ][ basehttp ][ 16440 ][ 139721573230336 ] ==> "GET /session_security/ping/?idleFor=900&_=1653391750232 HTTP/1.1" 200 8
[ INFO ][ 2022-05-24 12:44:15,331 ][ basehttp ][ 16440 ][ 139721573230336 ] ==> "GET /back-office/dashboard HTTP/1.1" 302 0
[ INFO ][ 2022-05-24 12:44:15,530 ][ basehttp ][ 16440 ][ 139721573230336 ] ==> "GET /back-office/login/ HTTP/1.1" 200 2418
[ INFO ][ 2022-05-24 13:21:37,336 ][ basehttp ][ 16440 ][ 139721573230336 ] ==> "GET /wait/failled HTTP/1.1" 301 0
[ ERROR ][ 2022-05-24 13:21:40,075 ][ log ][ 16440 ][ 139721573230336 ] ==> Internal Server Error: /wait/failled/
Traceback (most recent call last):
  File "/home/ymane/.local/lib/python3.8/site-packages/django/template/backends/django.py", line 61, in render
    return self.template.render(context)
  File "/home/ymane/.local/lib/python3.8/site-packages/django/template/base.py", line 171, in render
    return self._render(context)
  File "/home/ymane/.local/lib/python3.8/site-packages/django/template/base.py", line 163, in _render
    return self.nodelist.render(context)
  File "/home/ymane/.local/lib/python3.8/site-packages/django/template/base.py", line 936, in render
    bit = node.render_annotated(context)
  File "/home/ymane/.local/lib/python3.8/site-packages/django/template/base.py", line 903, in render_annotated
    return self.render(context)
  File "/home/ymane/.local/lib/python3.8/site-packages/django/template/loader_tags.py", line 127, in render
    compiled_parent = self.get_parent(context)
  File "/home/ymane/.local/lib/python3.8/site-packages/django/template/loader_tags.py", line 124, in get_parent
    return self.find_template(parent, context)
  File "/home/ymane/.local/lib/python3.8/site-packages/django/template/loader_tags.py", line 103, in find_template
    template, origin = context.template.engine.find_template(
  File "/home/ymane/.local/lib/python3.8/site-packages/django/template/engine.py", line 129, in find_template
    raise TemplateDoesNotExist(name, tried=tried)
django.template.exceptions.TemplateDoesNotExist: basepageKA.html

The above exception was the direct cause of the following exception:

Traceback (most recent call last):
  File "/home/ymane/.local/lib/python3.8/site-packages/django/core/handlers/exception.py", line 34, in inner
    response = get_response(request)
  File "/home/ymane/.local/lib/python3.8/site-packages/django/core/handlers/base.py", line 115, in _get_response
    response = self.process_exception_by_middleware(e, request)
  File "/home/ymane/.local/lib/python3.8/site-packages/django/core/handlers/base.py", line 113, in _get_response
    response = wrapped_callback(request, *callback_args, **callback_kwargs)
  File "/home/ymane/Téléchargements/essaie/website/views/waiting_page.py", line 38, in failled
    return render(request,'website/front/failled.html',context)
  File "/home/ymane/.local/lib/python3.8/site-packages/django/shortcuts.py", line 19, in render
    content = loader.render_to_string(template_name, context, request, using=using)
  File "/home/ymane/.local/lib/python3.8/site-packages/django/template/loader.py", line 62, in render_to_string
    return template.render(context, request)
  File "/home/ymane/.local/lib/python3.8/site-packages/django/template/backends/django.py", line 63, in render
    reraise(exc, self.backend)
  File "/home/ymane/.local/lib/python3.8/site-packages/django/template/backends/django.py", line 84, in reraise
    raise new from exc
django.template.exceptions.TemplateDoesNotExist: basepageKA.html
[ ERROR ][ 2022-05-24 13:21:40,289 ][ basehttp ][ 16440 ][ 139721573230336 ] ==> "GET /wait/failled/ HTTP/1.1" 500 150618
[ INFO ][ 2022-05-24 14:07:09,003 ][ basehttp ][ 16440 ][ 139721573230336 ] ==> "POST /back-office/login/ HTTP/1.1" 302 0
[ INFO ][ 2022-05-24 14:07:13,231 ][ basehttp ][ 16440 ][ 139721573230336 ] ==> "GET /back-office/dashboard HTTP/1.1" 200 167564
[ WARNING ][ 2022-05-24 14:07:17,076 ][ basehttp ][ 16440 ][ 139721563264768 ] ==> "GET /static/website/back/fonts/fontawesome-webfont.woff2%3Fv=4.6.3 HTTP/1.1" 404 1887
[ WARNING ][ 2022-05-24 14:07:17,078 ][ basehttp ][ 16440 ][ 139721573230336 ] ==> "GET /static/website/back/fonts/materialdesignicons-webfont.woff2%3Fv=1.6.50 HTTP/1.1" 404 1914
[ WARNING ][ 2022-05-24 14:07:17,095 ][ basehttp ][ 16440 ][ 139721573230336 ] ==> "GET /static/website/back/fonts/fontawesome-webfont.woff%3Fv=4.6.3 HTTP/1.1" 404 1884
[ WARNING ][ 2022-05-24 14:07:17,324 ][ basehttp ][ 16440 ][ 139721563264768 ] ==> "GET /static/website/back/fonts/fontawesome-webfont.ttf%3Fv=4.6.3 HTTP/1.1" 404 1881
[ WARNING ][ 2022-05-24 14:07:17,335 ][ basehttp ][ 16440 ][ 139721573230336 ] ==> "GET /static/website/back/fonts/materialdesignicons-webfont.woff%3Fv=1.6.50 HTTP/1.1" 404 1911
[ WARNING ][ 2022-05-24 14:07:17,587 ][ basehttp ][ 16440 ][ 139721563264768 ] ==> "GET /static/website/back/fonts/materialdesignicons-webfont.ttf%3Fv=1.6.50 HTTP/1.1" 404 1908
[ INFO ][ 2022-05-24 14:21:14,422 ][ basehttp ][ 16440 ][ 139721563264768 ] ==> "GET /session_security/ping/?idleFor=646&_=1653401234832 HTTP/1.1" 200 3
[ INFO ][ 2022-05-24 14:24:31,598 ][ basehttp ][ 16440 ][ 139721563264768 ] ==> "GET /session_security/ping/?idleFor=840&_=1653401234833 HTTP/1.1" 200 3
[ INFO ][ 2022-05-24 14:24:53,372 ][ basehttp ][ 16440 ][ 139721563264768 ] ==> "GET /session_security/ping/?idleFor=0&_=1653401234834 HTTP/1.1" 200 1
[ INFO ][ 2022-05-24 14:24:56,295 ][ basehttp ][ 16440 ][ 139721563264768 ] ==> "GET /back-office/dashboard HTTP/1.1" 200 167564
[ WARNING ][ 2022-05-24 14:24:56,502 ][ basehttp ][ 16440 ][ 139721573230336 ] ==> "GET /static/website/back/fonts/materialdesignicons-webfont.woff2%3Fv=1.6.50 HTTP/1.1" 404 1914
[ WARNING ][ 2022-05-24 14:24:56,506 ][ basehttp ][ 16440 ][ 139721563264768 ] ==> "GET /static/website/back/fonts/fontawesome-webfont.woff2%3Fv=4.6.3 HTTP/1.1" 404 1887
[ WARNING ][ 2022-05-24 14:24:56,704 ][ basehttp ][ 16440 ][ 139721563264768 ] ==> "GET /static/website/back/fonts/materialdesignicons-webfont.woff%3Fv=1.6.50 HTTP/1.1" 404 1911
[ WARNING ][ 2022-05-24 14:24:56,717 ][ basehttp ][ 16440 ][ 139721563264768 ] ==> "GET /static/website/back/fonts/fontawesome-webfont.woff%3Fv=4.6.3 HTTP/1.1" 404 1884
[ WARNING ][ 2022-05-24 14:24:56,820 ][ basehttp ][ 16440 ][ 139721563264768 ] ==> "GET /static/website/back/fonts/materialdesignicons-webfont.ttf%3Fv=1.6.50 HTTP/1.1" 404 1908
[ WARNING ][ 2022-05-24 14:24:56,904 ][ basehttp ][ 16440 ][ 139721563264768 ] ==> "GET /static/website/back/fonts/fontawesome-webfont.ttf%3Fv=4.6.3 HTTP/1.1" 404 1881
[ INFO ][ 2022-05-24 14:24:59,519 ][ basehttp ][ 16440 ][ 139721563264768 ] ==> "GET /back-office/dashboard HTTP/1.1" 200 167564
[ WARNING ][ 2022-05-24 14:24:59,722 ][ basehttp ][ 16440 ][ 139721573230336 ] ==> "GET /static/website/back/fonts/fontawesome-webfont.woff2%3Fv=4.6.3 HTTP/1.1" 404 1887
[ WARNING ][ 2022-05-24 14:24:59,730 ][ basehttp ][ 16440 ][ 139721563264768 ] ==> "GET /static/website/back/fonts/materialdesignicons-webfont.woff2%3Fv=1.6.50 HTTP/1.1" 404 1914
[ WARNING ][ 2022-05-24 14:24:59,878 ][ basehttp ][ 16440 ][ 139721563264768 ] ==> "GET /static/website/back/fonts/fontawesome-webfont.woff%3Fv=4.6.3 HTTP/1.1" 404 1884
[ WARNING ][ 2022-05-24 14:24:59,893 ][ basehttp ][ 16440 ][ 139721563264768 ] ==> "GET /static/website/back/fonts/materialdesignicons-webfont.woff%3Fv=1.6.50 HTTP/1.1" 404 1911
[ WARNING ][ 2022-05-24 14:24:59,984 ][ basehttp ][ 16440 ][ 139721563264768 ] ==> "GET /static/website/back/fonts/fontawesome-webfont.ttf%3Fv=4.6.3 HTTP/1.1" 404 1881
[ WARNING ][ 2022-05-24 14:24:59,992 ][ basehttp ][ 16440 ][ 139721573230336 ] ==> "GET /static/website/back/fonts/materialdesignicons-webfont.ttf%3Fv=1.6.50 HTTP/1.1" 404 1908
[ INFO ][ 2022-05-24 14:39:01,949 ][ basehttp ][ 16440 ][ 139721573230336 ] ==> "GET /session_security/ping/?idleFor=345&_=1653402299744 HTTP/1.1" 200 3
[ INFO ][ 2022-05-24 14:47:21,295 ][ basehttp ][ 16440 ][ 139721563264768 ] ==> "GET /session_security/ping/?idleFor=840&_=1653402299745 HTTP/1.1" 200 3
[ INFO ][ 2022-05-24 14:48:22,185 ][ basehttp ][ 16440 ][ 139721563264768 ] ==> "GET /session_security/ping/?idleFor=900&_=1653402299746 HTTP/1.1" 200 8
[ INFO ][ 2022-05-24 14:48:22,494 ][ basehttp ][ 16440 ][ 139721563264768 ] ==> "GET /back-office/dashboard HTTP/1.1" 302 0
[ INFO ][ 2022-05-24 14:48:22,669 ][ basehttp ][ 16440 ][ 139721563264768 ] ==> "GET /back-office/login/ HTTP/1.1" 200 2418
[ INFO ][ 2022-05-24 19:04:28,764 ][ autoreload ][ 3880 ][ 140303042901824 ] ==> Watching for file changes with StatReloader
[ INFO ][ 2022-05-24 19:06:30,084 ][ basehttp ][ 3880 ][ 140302838060800 ] ==> "GET / HTTP/1.1" 200 8390
[ INFO ][ 2022-05-24 19:06:30,485 ][ basehttp ][ 3880 ][ 140302757132032 ] ==> "GET /static/website/front/css/style.css HTTP/1.1" 304 0
[ WARNING ][ 2022-05-24 19:06:30,941 ][ basehttp ][ 3880 ][ 140302838060800 ] ==> "GET /static/fonts.googleapis.com/css%3Ffamily%3DAsap%3A400%2C400i%2C500%2C500i%2C700%2C700i HTTP/1.1" 404 1920
[ WARNING ][ 2022-05-24 19:06:33,641 ][ basehttp ][ 3880 ][ 140302757132032 ] ==> "GET /website/front/js/main.js HTTP/1.1" 404 4451
[ WARNING ][ 2022-05-24 19:06:34,255 ][ basehttp ][ 3880 ][ 140302757132032 ] ==> "GET /favicon.ico HTTP/1.1" 404 4412
[ INFO ][ 2022-05-24 19:06:42,086 ][ basehttp ][ 3880 ][ 140302757132032 ] ==> "GET /back-office/ HTTP/1.1" 200 2418
[ INFO ][ 2022-05-24 19:07:09,093 ][ basehttp ][ 3880 ][ 140302757132032 ] ==> "GET /ajax/load-lieu_depart/?compagnie_id=2 HTTP/1.1" 200 160
[ INFO ][ 2022-05-24 19:07:09,496 ][ basehttp ][ 3880 ][ 140302838060800 ] ==> "GET /ajax/load-destination/?compagnie_id=2 HTTP/1.1" 200 157
[ INFO ][ 2022-05-24 19:07:15,535 ][ basehttp ][ 3880 ][ 140302838060800 ] ==> "POST / HTTP/1.1" 302 0
[ INFO ][ 2022-05-24 19:07:15,759 ][ basehttp ][ 3880 ][ 140302838060800 ] ==> "GET /wait//34 HTTP/1.1" 200 2722
[ INFO ][ 2022-05-24 19:07:16,376 ][ basehttp ][ 3880 ][ 140302838060800 ] ==> "GET /static/website/front/images/bleus.jpg HTTP/1.1" 304 0
[ INFO ][ 2022-05-24 20:56:52,165 ][ basehttp ][ 3880 ][ 140302757132032 ] ==> "POST /back-office/login/ HTTP/1.1" 302 0
[ INFO ][ 2022-05-24 20:56:53,097 ][ basehttp ][ 3880 ][ 140302757132032 ] ==> "GET /back-office/dashboard HTTP/1.1" 200 172067
[ INFO ][ 2022-05-24 20:56:53,442 ][ basehttp ][ 3880 ][ 140302757132032 ] ==> "GET /static/website/back/js/valider.js HTTP/1.1" 304 0
[ WARNING ][ 2022-05-24 20:56:54,673 ][ basehttp ][ 3880 ][ 140302838060800 ] ==> "GET /static/website/back/fonts/materialdesignicons-webfont.woff2%3Fv=1.6.50 HTTP/1.1" 404 1914
[ WARNING ][ 2022-05-24 20:56:54,677 ][ basehttp ][ 3880 ][ 140302757132032 ] ==> "GET /static/website/back/fonts/fontawesome-webfont.woff2%3Fv=4.6.3 HTTP/1.1" 404 1887
[ WARNING ][ 2022-05-24 20:56:55,073 ][ basehttp ][ 3880 ][ 140302757132032 ] ==> "GET /static/website/back/fonts/materialdesignicons-webfont.woff%3Fv=1.6.50 HTTP/1.1" 404 1911
[ WARNING ][ 2022-05-24 20:56:55,081 ][ basehttp ][ 3880 ][ 140302838060800 ] ==> "GET /static/website/back/fonts/fontawesome-webfont.woff%3Fv=4.6.3 HTTP/1.1" 404 1884
[ WARNING ][ 2022-05-24 20:56:55,146 ][ basehttp ][ 3880 ][ 140302838060800 ] ==> "GET /static/website/back/fonts/materialdesignicons-webfont.ttf%3Fv=1.6.50 HTTP/1.1" 404 1908
[ WARNING ][ 2022-05-24 20:56:55,261 ][ basehttp ][ 3880 ][ 140302838060800 ] ==> "GET /static/website/back/fonts/fontawesome-webfont.ttf%3Fv=4.6.3 HTTP/1.1" 404 1881
[ ERROR ][ 2022-05-24 21:10:53,693 ][ log ][ 3880 ][ 140302838060800 ] ==> Internal Server Error: /session_security/ping/
Traceback (most recent call last):
  File "/home/ymane/.local/lib/python3.8/site-packages/django/contrib/sessions/backends/base.py", line 199, in _get_session
    return self._session_cache
AttributeError: 'SessionStore' object has no attribute '_session_cache'

During handling of the above exception, another exception occurred:

Traceback (most recent call last):
  File "/home/ymane/.local/lib/python3.8/site-packages/django/db/backends/base/base.py", line 220, in ensure_connection
    self.connect()
  File "/home/ymane/.local/lib/python3.8/site-packages/django/utils/asyncio.py", line 26, in inner
    return func(*args, **kwargs)
  File "/home/ymane/.local/lib/python3.8/site-packages/django/db/backends/base/base.py", line 197, in connect
    self.connection = self.get_new_connection(conn_params)
  File "/home/ymane/.local/lib/python3.8/site-packages/django/utils/asyncio.py", line 26, in inner
    return func(*args, **kwargs)
  File "/home/ymane/.local/lib/python3.8/site-packages/django/db/backends/sqlite3/base.py", line 199, in get_new_connection
    conn = Database.connect(**conn_params)
sqlite3.OperationalError: unable to open database file

The above exception was the direct cause of the following exception:

Traceback (most recent call last):
  File "/home/ymane/.local/lib/python3.8/site-packages/django/core/handlers/exception.py", line 34, in inner
    response = get_response(request)
  File "/home/ymane/.local/lib/python3.8/site-packages/django/utils/deprecation.py", line 93, in __call__
    response = self.process_request(request)
  File "/home/ymane/Téléchargements/EASYTRANS/session_security/middleware.py", line 62, in process_request
  File "/home/ymane/.local/lib/python3.8/site-packages/django/utils/functional.py", line 224, in inner
    self._setup()
  File "/home/ymane/.local/lib/python3.8/site-packages/django/utils/functional.py", line 360, in _setup
    self._wrapped = self._setupfunc()
  File "/home/ymane/.local/lib/python3.8/site-packages/django/contrib/auth/middleware.py", line 24, in <lambda>
    request.user = SimpleLazyObject(lambda: get_user(request))
  File "/home/ymane/.local/lib/python3.8/site-packages/django/contrib/auth/middleware.py", line 12, in get_user
    request._cached_user = auth.get_user(request)
  File "/home/ymane/.local/lib/python3.8/site-packages/django/contrib/auth/__init__.py", line 173, in get_user
    user_id = _get_user_session_key(request)
  File "/home/ymane/.local/lib/python3.8/site-packages/django/contrib/auth/__init__.py", line 58, in _get_user_session_key
    return get_user_model()._meta.pk.to_python(request.session[SESSION_KEY])
  File "/home/ymane/.local/lib/python3.8/site-packages/django/contrib/sessions/backends/base.py", line 64, in __getitem__
    return self._session[key]
  File "/home/ymane/.local/lib/python3.8/site-packages/django/contrib/sessions/backends/base.py", line 204, in _get_session
    self._session_cache = self.load()
  File "/home/ymane/.local/lib/python3.8/site-packages/django/contrib/sessions/backends/db.py", line 43, in load
    s = self._get_session_from_db()
  File "/home/ymane/.local/lib/python3.8/site-packages/django/contrib/sessions/backends/db.py", line 32, in _get_session_from_db
    return self.model.objects.get(
  File "/home/ymane/.local/lib/python3.8/site-packages/django/db/models/manager.py", line 82, in manager_method
    return getattr(self.get_queryset(), name)(*args, **kwargs)
  File "/home/ymane/.local/lib/python3.8/site-packages/django/db/models/query.py", line 411, in get
    num = len(clone)
  File "/home/ymane/.local/lib/python3.8/site-packages/django/db/models/query.py", line 258, in __len__
    self._fetch_all()
  File "/home/ymane/.local/lib/python3.8/site-packages/django/db/models/query.py", line 1261, in _fetch_all
    self._result_cache = list(self._iterable_class(self))
  File "/home/ymane/.local/lib/python3.8/site-packages/django/db/models/query.py", line 57, in __iter__
    results = compiler.execute_sql(chunked_fetch=self.chunked_fetch, chunk_size=self.chunk_size)
  File "/home/ymane/.local/lib/python3.8/site-packages/django/db/models/sql/compiler.py", line 1150, in execute_sql
    cursor = self.connection.cursor()
  File "/home/ymane/.local/lib/python3.8/site-packages/django/utils/asyncio.py", line 26, in inner
    return func(*args, **kwargs)
  File "/home/ymane/.local/lib/python3.8/site-packages/django/db/backends/base/base.py", line 260, in cursor
    return self._cursor()
  File "/home/ymane/.local/lib/python3.8/site-packages/django/db/backends/base/base.py", line 236, in _cursor
    self.ensure_connection()
  File "/home/ymane/.local/lib/python3.8/site-packages/django/utils/asyncio.py", line 26, in inner
    return func(*args, **kwargs)
  File "/home/ymane/.local/lib/python3.8/site-packages/django/db/backends/base/base.py", line 220, in ensure_connection
    self.connect()
  File "/home/ymane/.local/lib/python3.8/site-packages/django/db/utils.py", line 90, in __exit__
    raise dj_exc_value.with_traceback(traceback) from exc_value
  File "/home/ymane/.local/lib/python3.8/site-packages/django/db/backends/base/base.py", line 220, in ensure_connection
    self.connect()
  File "/home/ymane/.local/lib/python3.8/site-packages/django/utils/asyncio.py", line 26, in inner
    return func(*args, **kwargs)
  File "/home/ymane/.local/lib/python3.8/site-packages/django/db/backends/base/base.py", line 197, in connect
    self.connection = self.get_new_connection(conn_params)
  File "/home/ymane/.local/lib/python3.8/site-packages/django/utils/asyncio.py", line 26, in inner
    return func(*args, **kwargs)
  File "/home/ymane/.local/lib/python3.8/site-packages/django/db/backends/sqlite3/base.py", line 199, in get_new_connection
    conn = Database.connect(**conn_params)
django.db.utils.OperationalError: unable to open database file
[ ERROR ][ 2022-05-24 21:10:53,964 ][ log ][ 3880 ][ 140302838060800 ] ==> Internal Server Error: /session_security/ping/
Traceback (most recent call last):
  File "/home/ymane/.local/lib/python3.8/site-packages/django/contrib/sessions/backends/base.py", line 199, in _get_session
    return self._session_cache
AttributeError: 'SessionStore' object has no attribute '_session_cache'

During handling of the above exception, another exception occurred:

Traceback (most recent call last):
  File "/home/ymane/.local/lib/python3.8/site-packages/django/db/backends/base/base.py", line 220, in ensure_connection
    self.connect()
  File "/home/ymane/.local/lib/python3.8/site-packages/django/utils/asyncio.py", line 26, in inner
    return func(*args, **kwargs)
  File "/home/ymane/.local/lib/python3.8/site-packages/django/db/backends/base/base.py", line 197, in connect
    self.connection = self.get_new_connection(conn_params)
  File "/home/ymane/.local/lib/python3.8/site-packages/django/utils/asyncio.py", line 26, in inner
    return func(*args, **kwargs)
  File "/home/ymane/.local/lib/python3.8/site-packages/django/db/backends/sqlite3/base.py", line 199, in get_new_connection
    conn = Database.connect(**conn_params)
sqlite3.OperationalError: unable to open database file

The above exception was the direct cause of the following exception:

Traceback (most recent call last):
  File "/home/ymane/.local/lib/python3.8/site-packages/django/core/handlers/exception.py", line 34, in inner
    response = get_response(request)
  File "/home/ymane/.local/lib/python3.8/site-packages/django/utils/deprecation.py", line 96, in __call__
    response = self.process_response(request, response)
  File "/home/ymane/Téléchargements/EASYTRANS/request/middleware.py", line 36, in process_response
  File "/home/ymane/.local/lib/python3.8/site-packages/django/utils/functional.py", line 224, in inner
    self._setup()
  File "/home/ymane/.local/lib/python3.8/site-packages/django/utils/functional.py", line 360, in _setup
    self._wrapped = self._setupfunc()
  File "/home/ymane/.local/lib/python3.8/site-packages/django/contrib/auth/middleware.py", line 24, in <lambda>
    request.user = SimpleLazyObject(lambda: get_user(request))
  File "/home/ymane/.local/lib/python3.8/site-packages/django/contrib/auth/middleware.py", line 12, in get_user
    request._cached_user = auth.get_user(request)
  File "/home/ymane/.local/lib/python3.8/site-packages/django/contrib/auth/__init__.py", line 173, in get_user
    user_id = _get_user_session_key(request)
  File "/home/ymane/.local/lib/python3.8/site-packages/django/contrib/auth/__init__.py", line 58, in _get_user_session_key
    return get_user_model()._meta.pk.to_python(request.session[SESSION_KEY])
  File "/home/ymane/.local/lib/python3.8/site-packages/django/contrib/sessions/backends/base.py", line 64, in __getitem__
    return self._session[key]
  File "/home/ymane/.local/lib/python3.8/site-packages/django/contrib/sessions/backends/base.py", line 204, in _get_session
    self._session_cache = self.load()
  File "/home/ymane/.local/lib/python3.8/site-packages/django/contrib/sessions/backends/db.py", line 43, in load
    s = self._get_session_from_db()
  File "/home/ymane/.local/lib/python3.8/site-packages/django/contrib/sessions/backends/db.py", line 32, in _get_session_from_db
    return self.model.objects.get(
  File "/home/ymane/.local/lib/python3.8/site-packages/django/db/models/manager.py", line 82, in manager_method
    return getattr(self.get_queryset(), name)(*args, **kwargs)
  File "/home/ymane/.local/lib/python3.8/site-packages/django/db/models/query.py", line 411, in get
    num = len(clone)
  File "/home/ymane/.local/lib/python3.8/site-packages/django/db/models/query.py", line 258, in __len__
    self._fetch_all()
  File "/home/ymane/.local/lib/python3.8/site-packages/django/db/models/query.py", line 1261, in _fetch_all
    self._result_cache = list(self._iterable_class(self))
  File "/home/ymane/.local/lib/python3.8/site-packages/django/db/models/query.py", line 57, in __iter__
    results = compiler.execute_sql(chunked_fetch=self.chunked_fetch, chunk_size=self.chunk_size)
  File "/home/ymane/.local/lib/python3.8/site-packages/django/db/models/sql/compiler.py", line 1150, in execute_sql
    cursor = self.connection.cursor()
  File "/home/ymane/.local/lib/python3.8/site-packages/django/utils/asyncio.py", line 26, in inner
    return func(*args, **kwargs)
  File "/home/ymane/.local/lib/python3.8/site-packages/django/db/backends/base/base.py", line 260, in cursor
    return self._cursor()
  File "/home/ymane/.local/lib/python3.8/site-packages/django/db/backends/base/base.py", line 236, in _cursor
    self.ensure_connection()
  File "/home/ymane/.local/lib/python3.8/site-packages/django/utils/asyncio.py", line 26, in inner
    return func(*args, **kwargs)
  File "/home/ymane/.local/lib/python3.8/site-packages/django/db/backends/base/base.py", line 220, in ensure_connection
    self.connect()
  File "/home/ymane/.local/lib/python3.8/site-packages/django/db/utils.py", line 90, in __exit__
    raise dj_exc_value.with_traceback(traceback) from exc_value
  File "/home/ymane/.local/lib/python3.8/site-packages/django/db/backends/base/base.py", line 220, in ensure_connection
    self.connect()
  File "/home/ymane/.local/lib/python3.8/site-packages/django/utils/asyncio.py", line 26, in inner
    return func(*args, **kwargs)
  File "/home/ymane/.local/lib/python3.8/site-packages/django/db/backends/base/base.py", line 197, in connect
    self.connection = self.get_new_connection(conn_params)
  File "/home/ymane/.local/lib/python3.8/site-packages/django/utils/asyncio.py", line 26, in inner
    return func(*args, **kwargs)
  File "/home/ymane/.local/lib/python3.8/site-packages/django/db/backends/sqlite3/base.py", line 199, in get_new_connection
    conn = Database.connect(**conn_params)
django.db.utils.OperationalError: unable to open database file
[ ERROR ][ 2022-05-24 21:10:54,054 ][ log ][ 3880 ][ 140302838060800 ] ==> Internal Server Error: /session_security/ping/
Traceback (most recent call last):
  File "/home/ymane/.local/lib/python3.8/site-packages/django/contrib/sessions/backends/base.py", line 199, in _get_session
    return self._session_cache
AttributeError: 'SessionStore' object has no attribute '_session_cache'

During handling of the above exception, another exception occurred:

Traceback (most recent call last):
  File "/home/ymane/.local/lib/python3.8/site-packages/django/db/backends/base/base.py", line 220, in ensure_connection
    self.connect()
  File "/home/ymane/.local/lib/python3.8/site-packages/django/utils/asyncio.py", line 26, in inner
    return func(*args, **kwargs)
  File "/home/ymane/.local/lib/python3.8/site-packages/django/db/backends/base/base.py", line 197, in connect
    self.connection = self.get_new_connection(conn_params)
  File "/home/ymane/.local/lib/python3.8/site-packages/django/utils/asyncio.py", line 26, in inner
    return func(*args, **kwargs)
  File "/home/ymane/.local/lib/python3.8/site-packages/django/db/backends/sqlite3/base.py", line 199, in get_new_connection
    conn = Database.connect(**conn_params)
sqlite3.OperationalError: unable to open database file

The above exception was the direct cause of the following exception:

Traceback (most recent call last):
  File "/home/ymane/.local/lib/python3.8/site-packages/django/core/handlers/exception.py", line 34, in inner
    response = get_response(request)
  File "/home/ymane/.local/lib/python3.8/site-packages/django/utils/deprecation.py", line 96, in __call__
    response = self.process_response(request, response)
  File "/home/ymane/.local/lib/python3.8/site-packages/django/contrib/sessions/middleware.py", line 47, in process_response
    if request.session.get_expire_at_browser_close():
  File "/home/ymane/.local/lib/python3.8/site-packages/django/contrib/sessions/backends/base.py", line 291, in get_expire_at_browser_close
    if self.get('_session_expiry') is None:
  File "/home/ymane/.local/lib/python3.8/site-packages/django/contrib/sessions/backends/base.py", line 75, in get
    return self._session.get(key, default)
  File "/home/ymane/.local/lib/python3.8/site-packages/django/contrib/sessions/backends/base.py", line 204, in _get_session
    self._session_cache = self.load()
  File "/home/ymane/.local/lib/python3.8/site-packages/django/contrib/sessions/backends/db.py", line 43, in load
    s = self._get_session_from_db()
  File "/home/ymane/.local/lib/python3.8/site-packages/django/contrib/sessions/backends/db.py", line 32, in _get_session_from_db
    return self.model.objects.get(
  File "/home/ymane/.local/lib/python3.8/site-packages/django/db/models/manager.py", line 82, in manager_method
    return getattr(self.get_queryset(), name)(*args, **kwargs)
  File "/home/ymane/.local/lib/python3.8/site-packages/django/db/models/query.py", line 411, in get
    num = len(clone)
  File "/home/ymane/.local/lib/python3.8/site-packages/django/db/models/query.py", line 258, in __len__
    self._fetch_all()
  File "/home/ymane/.local/lib/python3.8/site-packages/django/db/models/query.py", line 1261, in _fetch_all
    self._result_cache = list(self._iterable_class(self))
  File "/home/ymane/.local/lib/python3.8/site-packages/django/db/models/query.py", line 57, in __iter__
    results = compiler.execute_sql(chunked_fetch=self.chunked_fetch, chunk_size=self.chunk_size)
  File "/home/ymane/.local/lib/python3.8/site-packages/django/db/models/sql/compiler.py", line 1150, in execute_sql
    cursor = self.connection.cursor()
  File "/home/ymane/.local/lib/python3.8/site-packages/django/utils/asyncio.py", line 26, in inner
    return func(*args, **kwargs)
  File "/home/ymane/.local/lib/python3.8/site-packages/django/db/backends/base/base.py", line 260, in cursor
    return self._cursor()
  File "/home/ymane/.local/lib/python3.8/site-packages/django/db/backends/base/base.py", line 236, in _cursor
    self.ensure_connection()
  File "/home/ymane/.local/lib/python3.8/site-packages/django/utils/asyncio.py", line 26, in inner
    return func(*args, **kwargs)
  File "/home/ymane/.local/lib/python3.8/site-packages/django/db/backends/base/base.py", line 220, in ensure_connection
    self.connect()
  File "/home/ymane/.local/lib/python3.8/site-packages/django/db/utils.py", line 90, in __exit__
    raise dj_exc_value.with_traceback(traceback) from exc_value
  File "/home/ymane/.local/lib/python3.8/site-packages/django/db/backends/base/base.py", line 220, in ensure_connection
    self.connect()
  File "/home/ymane/.local/lib/python3.8/site-packages/django/utils/asyncio.py", line 26, in inner
    return func(*args, **kwargs)
  File "/home/ymane/.local/lib/python3.8/site-packages/django/db/backends/base/base.py", line 197, in connect
    self.connection = self.get_new_connection(conn_params)
  File "/home/ymane/.local/lib/python3.8/site-packages/django/utils/asyncio.py", line 26, in inner
    return func(*args, **kwargs)
  File "/home/ymane/.local/lib/python3.8/site-packages/django/db/backends/sqlite3/base.py", line 199, in get_new_connection
    conn = Database.connect(**conn_params)
django.db.utils.OperationalError: unable to open database file
[ ERROR ][ 2022-05-24 21:10:54,082 ][ basehttp ][ 3880 ][ 140302838060800 ] ==> "GET /session_security/ping/?idleFor=382&_=1653425814846 HTTP/1.1" 500 28704
[ ERROR ][ 2022-05-24 21:16:52,702 ][ log ][ 3880 ][ 140302838060800 ] ==> Internal Server Error: /wait//27
Traceback (most recent call last):
  File "/home/ymane/.local/lib/python3.8/site-packages/django/db/backends/base/base.py", line 220, in ensure_connection
    self.connect()
  File "/home/ymane/.local/lib/python3.8/site-packages/django/utils/asyncio.py", line 26, in inner
    return func(*args, **kwargs)
  File "/home/ymane/.local/lib/python3.8/site-packages/django/db/backends/base/base.py", line 197, in connect
    self.connection = self.get_new_connection(conn_params)
  File "/home/ymane/.local/lib/python3.8/site-packages/django/utils/asyncio.py", line 26, in inner
    return func(*args, **kwargs)
  File "/home/ymane/.local/lib/python3.8/site-packages/django/db/backends/sqlite3/base.py", line 199, in get_new_connection
    conn = Database.connect(**conn_params)
sqlite3.OperationalError: unable to open database file

The above exception was the direct cause of the following exception:

Traceback (most recent call last):
  File "/home/ymane/.local/lib/python3.8/site-packages/django/core/handlers/exception.py", line 34, in inner
    response = get_response(request)
  File "/home/ymane/.local/lib/python3.8/site-packages/django/core/handlers/base.py", line 115, in _get_response
    response = self.process_exception_by_middleware(e, request)
  File "/home/ymane/.local/lib/python3.8/site-packages/django/core/handlers/base.py", line 113, in _get_response
    response = wrapped_callback(request, *callback_args, **callback_kwargs)
  File "/home/ymane/Téléchargements/EASYTRANS/website/views/waiting_page.py", line 17, in waiting_page
  File "/home/ymane/.local/lib/python3.8/site-packages/django/db/models/manager.py", line 82, in manager_method
    return getattr(self.get_queryset(), name)(*args, **kwargs)
  File "/home/ymane/.local/lib/python3.8/site-packages/django/db/models/query.py", line 411, in get
    num = len(clone)
  File "/home/ymane/.local/lib/python3.8/site-packages/django/db/models/query.py", line 258, in __len__
    self._fetch_all()
  File "/home/ymane/.local/lib/python3.8/site-packages/django/db/models/query.py", line 1261, in _fetch_all
    self._result_cache = list(self._iterable_class(self))
  File "/home/ymane/.local/lib/python3.8/site-packages/django/db/models/query.py", line 57, in __iter__
    results = compiler.execute_sql(chunked_fetch=self.chunked_fetch, chunk_size=self.chunk_size)
  File "/home/ymane/.local/lib/python3.8/site-packages/django/db/models/sql/compiler.py", line 1150, in execute_sql
    cursor = self.connection.cursor()
  File "/home/ymane/.local/lib/python3.8/site-packages/django/utils/asyncio.py", line 26, in inner
    return func(*args, **kwargs)
  File "/home/ymane/.local/lib/python3.8/site-packages/django/db/backends/base/base.py", line 260, in cursor
    return self._cursor()
  File "/home/ymane/.local/lib/python3.8/site-packages/django/db/backends/base/base.py", line 236, in _cursor
    self.ensure_connection()
  File "/home/ymane/.local/lib/python3.8/site-packages/django/utils/asyncio.py", line 26, in inner
    return func(*args, **kwargs)
  File "/home/ymane/.local/lib/python3.8/site-packages/django/db/backends/base/base.py", line 220, in ensure_connection
    self.connect()
  File "/home/ymane/.local/lib/python3.8/site-packages/django/db/utils.py", line 90, in __exit__
    raise dj_exc_value.with_traceback(traceback) from exc_value
  File "/home/ymane/.local/lib/python3.8/site-packages/django/db/backends/base/base.py", line 220, in ensure_connection
    self.connect()
  File "/home/ymane/.local/lib/python3.8/site-packages/django/utils/asyncio.py", line 26, in inner
    return func(*args, **kwargs)
  File "/home/ymane/.local/lib/python3.8/site-packages/django/db/backends/base/base.py", line 197, in connect
    self.connection = self.get_new_connection(conn_params)
  File "/home/ymane/.local/lib/python3.8/site-packages/django/utils/asyncio.py", line 26, in inner
    return func(*args, **kwargs)
  File "/home/ymane/.local/lib/python3.8/site-packages/django/db/backends/sqlite3/base.py", line 199, in get_new_connection
    conn = Database.connect(**conn_params)
django.db.utils.OperationalError: unable to open database file
[ ERROR ][ 2022-05-24 21:16:52,801 ][ log ][ 3880 ][ 140302838060800 ] ==> Internal Server Error: /wait//27
Traceback (most recent call last):
  File "/home/ymane/.local/lib/python3.8/site-packages/django/db/backends/base/base.py", line 220, in ensure_connection
    self.connect()
  File "/home/ymane/.local/lib/python3.8/site-packages/django/utils/asyncio.py", line 26, in inner
    return func(*args, **kwargs)
  File "/home/ymane/.local/lib/python3.8/site-packages/django/db/backends/base/base.py", line 197, in connect
    self.connection = self.get_new_connection(conn_params)
  File "/home/ymane/.local/lib/python3.8/site-packages/django/utils/asyncio.py", line 26, in inner
    return func(*args, **kwargs)
  File "/home/ymane/.local/lib/python3.8/site-packages/django/db/backends/sqlite3/base.py", line 199, in get_new_connection
    conn = Database.connect(**conn_params)
sqlite3.OperationalError: unable to open database file

The above exception was the direct cause of the following exception:

Traceback (most recent call last):
  File "/home/ymane/.local/lib/python3.8/site-packages/django/core/handlers/exception.py", line 34, in inner
    response = get_response(request)
  File "/home/ymane/.local/lib/python3.8/site-packages/django/utils/deprecation.py", line 96, in __call__
    response = self.process_response(request, response)
  File "/home/ymane/Téléchargements/EASYTRANS/request/middleware.py", line 41, in process_response
  File "/home/ymane/Téléchargements/EASYTRANS/request/models.py", line 82, in from_http_request
  File "/home/ymane/Téléchargements/EASYTRANS/request/models.py", line 120, in save
  File "/home/ymane/.local/lib/python3.8/site-packages/django/db/models/base.py", line 745, in save
    self.save_base(using=using, force_insert=force_insert,
  File "/home/ymane/.local/lib/python3.8/site-packages/django/db/models/base.py", line 782, in save_base
    updated = self._save_table(
  File "/home/ymane/.local/lib/python3.8/site-packages/django/db/models/base.py", line 887, in _save_table
    results = self._do_insert(cls._base_manager, using, fields, returning_fields, raw)
  File "/home/ymane/.local/lib/python3.8/site-packages/django/db/models/base.py", line 924, in _do_insert
    return manager._insert(
  File "/home/ymane/.local/lib/python3.8/site-packages/django/db/models/manager.py", line 82, in manager_method
    return getattr(self.get_queryset(), name)(*args, **kwargs)
  File "/home/ymane/.local/lib/python3.8/site-packages/django/db/models/query.py", line 1204, in _insert
    return query.get_compiler(using=using).execute_sql(returning_fields)
  File "/home/ymane/.local/lib/python3.8/site-packages/django/db/models/sql/compiler.py", line 1390, in execute_sql
    with self.connection.cursor() as cursor:
  File "/home/ymane/.local/lib/python3.8/site-packages/django/utils/asyncio.py", line 26, in inner
    return func(*args, **kwargs)
  File "/home/ymane/.local/lib/python3.8/site-packages/django/db/backends/base/base.py", line 260, in cursor
    return self._cursor()
  File "/home/ymane/.local/lib/python3.8/site-packages/django/db/backends/base/base.py", line 236, in _cursor
    self.ensure_connection()
  File "/home/ymane/.local/lib/python3.8/site-packages/django/utils/asyncio.py", line 26, in inner
    return func(*args, **kwargs)
  File "/home/ymane/.local/lib/python3.8/site-packages/django/db/backends/base/base.py", line 220, in ensure_connection
    self.connect()
  File "/home/ymane/.local/lib/python3.8/site-packages/django/db/utils.py", line 90, in __exit__
    raise dj_exc_value.with_traceback(traceback) from exc_value
  File "/home/ymane/.local/lib/python3.8/site-packages/django/db/backends/base/base.py", line 220, in ensure_connection
    self.connect()
  File "/home/ymane/.local/lib/python3.8/site-packages/django/utils/asyncio.py", line 26, in inner
    return func(*args, **kwargs)
  File "/home/ymane/.local/lib/python3.8/site-packages/django/db/backends/base/base.py", line 197, in connect
    self.connection = self.get_new_connection(conn_params)
  File "/home/ymane/.local/lib/python3.8/site-packages/django/utils/asyncio.py", line 26, in inner
    return func(*args, **kwargs)
  File "/home/ymane/.local/lib/python3.8/site-packages/django/db/backends/sqlite3/base.py", line 199, in get_new_connection
    conn = Database.connect(**conn_params)
django.db.utils.OperationalError: unable to open database file
[ ERROR ][ 2022-05-24 21:16:52,823 ][ basehttp ][ 3880 ][ 140302838060800 ] ==> "GET /wait//27 HTTP/1.1" 500 190695
[ ERROR ][ 2022-05-24 21:16:54,620 ][ log ][ 3880 ][ 140302838060800 ] ==> Internal Server Error: /favicon.ico
Traceback (most recent call last):
  File "/home/ymane/.local/lib/python3.8/site-packages/django/db/backends/base/base.py", line 220, in ensure_connection
    self.connect()
  File "/home/ymane/.local/lib/python3.8/site-packages/django/utils/asyncio.py", line 26, in inner
    return func(*args, **kwargs)
  File "/home/ymane/.local/lib/python3.8/site-packages/django/db/backends/base/base.py", line 197, in connect
    self.connection = self.get_new_connection(conn_params)
  File "/home/ymane/.local/lib/python3.8/site-packages/django/utils/asyncio.py", line 26, in inner
    return func(*args, **kwargs)
  File "/home/ymane/.local/lib/python3.8/site-packages/django/db/backends/sqlite3/base.py", line 199, in get_new_connection
    conn = Database.connect(**conn_params)
sqlite3.OperationalError: unable to open database file

The above exception was the direct cause of the following exception:

Traceback (most recent call last):
  File "/home/ymane/.local/lib/python3.8/site-packages/django/core/handlers/exception.py", line 34, in inner
    response = get_response(request)
  File "/home/ymane/.local/lib/python3.8/site-packages/django/utils/deprecation.py", line 96, in __call__
    response = self.process_response(request, response)
  File "/home/ymane/Téléchargements/EASYTRANS/request/middleware.py", line 41, in process_response
  File "/home/ymane/Téléchargements/EASYTRANS/request/models.py", line 82, in from_http_request
  File "/home/ymane/Téléchargements/EASYTRANS/request/models.py", line 120, in save
  File "/home/ymane/.local/lib/python3.8/site-packages/django/db/models/base.py", line 745, in save
    self.save_base(using=using, force_insert=force_insert,
  File "/home/ymane/.local/lib/python3.8/site-packages/django/db/models/base.py", line 782, in save_base
    updated = self._save_table(
  File "/home/ymane/.local/lib/python3.8/site-packages/django/db/models/base.py", line 887, in _save_table
    results = self._do_insert(cls._base_manager, using, fields, returning_fields, raw)
  File "/home/ymane/.local/lib/python3.8/site-packages/django/db/models/base.py", line 924, in _do_insert
    return manager._insert(
  File "/home/ymane/.local/lib/python3.8/site-packages/django/db/models/manager.py", line 82, in manager_method
    return getattr(self.get_queryset(), name)(*args, **kwargs)
  File "/home/ymane/.local/lib/python3.8/site-packages/django/db/models/query.py", line 1204, in _insert
    return query.get_compiler(using=using).execute_sql(returning_fields)
  File "/home/ymane/.local/lib/python3.8/site-packages/django/db/models/sql/compiler.py", line 1390, in execute_sql
    with self.connection.cursor() as cursor:
  File "/home/ymane/.local/lib/python3.8/site-packages/django/utils/asyncio.py", line 26, in inner
    return func(*args, **kwargs)
  File "/home/ymane/.local/lib/python3.8/site-packages/django/db/backends/base/base.py", line 260, in cursor
    return self._cursor()
  File "/home/ymane/.local/lib/python3.8/site-packages/django/db/backends/base/base.py", line 236, in _cursor
    self.ensure_connection()
  File "/home/ymane/.local/lib/python3.8/site-packages/django/utils/asyncio.py", line 26, in inner
    return func(*args, **kwargs)
  File "/home/ymane/.local/lib/python3.8/site-packages/django/db/backends/base/base.py", line 220, in ensure_connection
    self.connect()
  File "/home/ymane/.local/lib/python3.8/site-packages/django/db/utils.py", line 90, in __exit__
    raise dj_exc_value.with_traceback(traceback) from exc_value
  File "/home/ymane/.local/lib/python3.8/site-packages/django/db/backends/base/base.py", line 220, in ensure_connection
    self.connect()
  File "/home/ymane/.local/lib/python3.8/site-packages/django/utils/asyncio.py", line 26, in inner
    return func(*args, **kwargs)
  File "/home/ymane/.local/lib/python3.8/site-packages/django/db/backends/base/base.py", line 197, in connect
    self.connection = self.get_new_connection(conn_params)
  File "/home/ymane/.local/lib/python3.8/site-packages/django/utils/asyncio.py", line 26, in inner
    return func(*args, **kwargs)
  File "/home/ymane/.local/lib/python3.8/site-packages/django/db/backends/sqlite3/base.py", line 199, in get_new_connection
    conn = Database.connect(**conn_params)
django.db.utils.OperationalError: unable to open database file
[ ERROR ][ 2022-05-24 21:16:54,640 ][ basehttp ][ 3880 ][ 140302838060800 ] ==> "GET /favicon.ico HTTP/1.1" 500 190451
[ ERROR ][ 2022-05-24 21:18:31,124 ][ log ][ 3880 ][ 140302757132032 ] ==> Internal Server Error: /session_security/ping/
Traceback (most recent call last):
  File "/home/ymane/.local/lib/python3.8/site-packages/django/contrib/sessions/backends/base.py", line 199, in _get_session
    return self._session_cache
AttributeError: 'SessionStore' object has no attribute '_session_cache'

During handling of the above exception, another exception occurred:

Traceback (most recent call last):
  File "/home/ymane/.local/lib/python3.8/site-packages/django/db/backends/base/base.py", line 220, in ensure_connection
    self.connect()
  File "/home/ymane/.local/lib/python3.8/site-packages/django/utils/asyncio.py", line 26, in inner
    return func(*args, **kwargs)
  File "/home/ymane/.local/lib/python3.8/site-packages/django/db/backends/base/base.py", line 197, in connect
    self.connection = self.get_new_connection(conn_params)
  File "/home/ymane/.local/lib/python3.8/site-packages/django/utils/asyncio.py", line 26, in inner
    return func(*args, **kwargs)
  File "/home/ymane/.local/lib/python3.8/site-packages/django/db/backends/sqlite3/base.py", line 199, in get_new_connection
    conn = Database.connect(**conn_params)
sqlite3.OperationalError: unable to open database file

The above exception was the direct cause of the following exception:

Traceback (most recent call last):
  File "/home/ymane/.local/lib/python3.8/site-packages/django/core/handlers/exception.py", line 34, in inner
    response = get_response(request)
  File "/home/ymane/.local/lib/python3.8/site-packages/django/utils/deprecation.py", line 93, in __call__
    response = self.process_request(request)
  File "/home/ymane/Téléchargements/EASYTRANS/session_security/middleware.py", line 62, in process_request
  File "/home/ymane/.local/lib/python3.8/site-packages/django/utils/functional.py", line 224, in inner
    self._setup()
  File "/home/ymane/.local/lib/python3.8/site-packages/django/utils/functional.py", line 360, in _setup
    self._wrapped = self._setupfunc()
  File "/home/ymane/.local/lib/python3.8/site-packages/django/contrib/auth/middleware.py", line 24, in <lambda>
    request.user = SimpleLazyObject(lambda: get_user(request))
  File "/home/ymane/.local/lib/python3.8/site-packages/django/contrib/auth/middleware.py", line 12, in get_user
    request._cached_user = auth.get_user(request)
  File "/home/ymane/.local/lib/python3.8/site-packages/django/contrib/auth/__init__.py", line 173, in get_user
    user_id = _get_user_session_key(request)
  File "/home/ymane/.local/lib/python3.8/site-packages/django/contrib/auth/__init__.py", line 58, in _get_user_session_key
    return get_user_model()._meta.pk.to_python(request.session[SESSION_KEY])
  File "/home/ymane/.local/lib/python3.8/site-packages/django/contrib/sessions/backends/base.py", line 64, in __getitem__
    return self._session[key]
  File "/home/ymane/.local/lib/python3.8/site-packages/django/contrib/sessions/backends/base.py", line 204, in _get_session
    self._session_cache = self.load()
  File "/home/ymane/.local/lib/python3.8/site-packages/django/contrib/sessions/backends/db.py", line 43, in load
    s = self._get_session_from_db()
  File "/home/ymane/.local/lib/python3.8/site-packages/django/contrib/sessions/backends/db.py", line 32, in _get_session_from_db
    return self.model.objects.get(
  File "/home/ymane/.local/lib/python3.8/site-packages/django/db/models/manager.py", line 82, in manager_method
    return getattr(self.get_queryset(), name)(*args, **kwargs)
  File "/home/ymane/.local/lib/python3.8/site-packages/django/db/models/query.py", line 411, in get
    num = len(clone)
  File "/home/ymane/.local/lib/python3.8/site-packages/django/db/models/query.py", line 258, in __len__
    self._fetch_all()
  File "/home/ymane/.local/lib/python3.8/site-packages/django/db/models/query.py", line 1261, in _fetch_all
    self._result_cache = list(self._iterable_class(self))
  File "/home/ymane/.local/lib/python3.8/site-packages/django/db/models/query.py", line 57, in __iter__
    results = compiler.execute_sql(chunked_fetch=self.chunked_fetch, chunk_size=self.chunk_size)
  File "/home/ymane/.local/lib/python3.8/site-packages/django/db/models/sql/compiler.py", line 1150, in execute_sql
    cursor = self.connection.cursor()
  File "/home/ymane/.local/lib/python3.8/site-packages/django/utils/asyncio.py", line 26, in inner
    return func(*args, **kwargs)
  File "/home/ymane/.local/lib/python3.8/site-packages/django/db/backends/base/base.py", line 260, in cursor
    return self._cursor()
  File "/home/ymane/.local/lib/python3.8/site-packages/django/db/backends/base/base.py", line 236, in _cursor
    self.ensure_connection()
  File "/home/ymane/.local/lib/python3.8/site-packages/django/utils/asyncio.py", line 26, in inner
    return func(*args, **kwargs)
  File "/home/ymane/.local/lib/python3.8/site-packages/django/db/backends/base/base.py", line 220, in ensure_connection
    self.connect()
  File "/home/ymane/.local/lib/python3.8/site-packages/django/db/utils.py", line 90, in __exit__
    raise dj_exc_value.with_traceback(traceback) from exc_value
  File "/home/ymane/.local/lib/python3.8/site-packages/django/db/backends/base/base.py", line 220, in ensure_connection
    self.connect()
  File "/home/ymane/.local/lib/python3.8/site-packages/django/utils/asyncio.py", line 26, in inner
    return func(*args, **kwargs)
  File "/home/ymane/.local/lib/python3.8/site-packages/django/db/backends/base/base.py", line 197, in connect
    self.connection = self.get_new_connection(conn_params)
  File "/home/ymane/.local/lib/python3.8/site-packages/django/utils/asyncio.py", line 26, in inner
    return func(*args, **kwargs)
  File "/home/ymane/.local/lib/python3.8/site-packages/django/db/backends/sqlite3/base.py", line 199, in get_new_connection
    conn = Database.connect(**conn_params)
django.db.utils.OperationalError: unable to open database file
[ ERROR ][ 2022-05-24 21:18:31,170 ][ log ][ 3880 ][ 140302757132032 ] ==> Internal Server Error: /session_security/ping/
Traceback (most recent call last):
  File "/home/ymane/.local/lib/python3.8/site-packages/django/contrib/sessions/backends/base.py", line 199, in _get_session
    return self._session_cache
AttributeError: 'SessionStore' object has no attribute '_session_cache'

During handling of the above exception, another exception occurred:

Traceback (most recent call last):
  File "/home/ymane/.local/lib/python3.8/site-packages/django/db/backends/base/base.py", line 220, in ensure_connection
    self.connect()
  File "/home/ymane/.local/lib/python3.8/site-packages/django/utils/asyncio.py", line 26, in inner
    return func(*args, **kwargs)
  File "/home/ymane/.local/lib/python3.8/site-packages/django/db/backends/base/base.py", line 197, in connect
    self.connection = self.get_new_connection(conn_params)
  File "/home/ymane/.local/lib/python3.8/site-packages/django/utils/asyncio.py", line 26, in inner
    return func(*args, **kwargs)
  File "/home/ymane/.local/lib/python3.8/site-packages/django/db/backends/sqlite3/base.py", line 199, in get_new_connection
    conn = Database.connect(**conn_params)
sqlite3.OperationalError: unable to open database file

The above exception was the direct cause of the following exception:

Traceback (most recent call last):
  File "/home/ymane/.local/lib/python3.8/site-packages/django/core/handlers/exception.py", line 34, in inner
    response = get_response(request)
  File "/home/ymane/.local/lib/python3.8/site-packages/django/utils/deprecation.py", line 96, in __call__
    response = self.process_response(request, response)
  File "/home/ymane/Téléchargements/EASYTRANS/request/middleware.py", line 36, in process_response
  File "/home/ymane/.local/lib/python3.8/site-packages/django/utils/functional.py", line 224, in inner
    self._setup()
  File "/home/ymane/.local/lib/python3.8/site-packages/django/utils/functional.py", line 360, in _setup
    self._wrapped = self._setupfunc()
  File "/home/ymane/.local/lib/python3.8/site-packages/django/contrib/auth/middleware.py", line 24, in <lambda>
    request.user = SimpleLazyObject(lambda: get_user(request))
  File "/home/ymane/.local/lib/python3.8/site-packages/django/contrib/auth/middleware.py", line 12, in get_user
    request._cached_user = auth.get_user(request)
  File "/home/ymane/.local/lib/python3.8/site-packages/django/contrib/auth/__init__.py", line 173, in get_user
    user_id = _get_user_session_key(request)
  File "/home/ymane/.local/lib/python3.8/site-packages/django/contrib/auth/__init__.py", line 58, in _get_user_session_key
    return get_user_model()._meta.pk.to_python(request.session[SESSION_KEY])
  File "/home/ymane/.local/lib/python3.8/site-packages/django/contrib/sessions/backends/base.py", line 64, in __getitem__
    return self._session[key]
  File "/home/ymane/.local/lib/python3.8/site-packages/django/contrib/sessions/backends/base.py", line 204, in _get_session
    self._session_cache = self.load()
  File "/home/ymane/.local/lib/python3.8/site-packages/django/contrib/sessions/backends/db.py", line 43, in load
    s = self._get_session_from_db()
  File "/home/ymane/.local/lib/python3.8/site-packages/django/contrib/sessions/backends/db.py", line 32, in _get_session_from_db
    return self.model.objects.get(
  File "/home/ymane/.local/lib/python3.8/site-packages/django/db/models/manager.py", line 82, in manager_method
    return getattr(self.get_queryset(), name)(*args, **kwargs)
  File "/home/ymane/.local/lib/python3.8/site-packages/django/db/models/query.py", line 411, in get
    num = len(clone)
  File "/home/ymane/.local/lib/python3.8/site-packages/django/db/models/query.py", line 258, in __len__
    self._fetch_all()
  File "/home/ymane/.local/lib/python3.8/site-packages/django/db/models/query.py", line 1261, in _fetch_all
    self._result_cache = list(self._iterable_class(self))
  File "/home/ymane/.local/lib/python3.8/site-packages/django/db/models/query.py", line 57, in __iter__
    results = compiler.execute_sql(chunked_fetch=self.chunked_fetch, chunk_size=self.chunk_size)
  File "/home/ymane/.local/lib/python3.8/site-packages/django/db/models/sql/compiler.py", line 1150, in execute_sql
    cursor = self.connection.cursor()
  File "/home/ymane/.local/lib/python3.8/site-packages/django/utils/asyncio.py", line 26, in inner
    return func(*args, **kwargs)
  File "/home/ymane/.local/lib/python3.8/site-packages/django/db/backends/base/base.py", line 260, in cursor
    return self._cursor()
  File "/home/ymane/.local/lib/python3.8/site-packages/django/db/backends/base/base.py", line 236, in _cursor
    self.ensure_connection()
  File "/home/ymane/.local/lib/python3.8/site-packages/django/utils/asyncio.py", line 26, in inner
    return func(*args, **kwargs)
  File "/home/ymane/.local/lib/python3.8/site-packages/django/db/backends/base/base.py", line 220, in ensure_connection
    self.connect()
  File "/home/ymane/.local/lib/python3.8/site-packages/django/db/utils.py", line 90, in __exit__
    raise dj_exc_value.with_traceback(traceback) from exc_value
  File "/home/ymane/.local/lib/python3.8/site-packages/django/db/backends/base/base.py", line 220, in ensure_connection
    self.connect()
  File "/home/ymane/.local/lib/python3.8/site-packages/django/utils/asyncio.py", line 26, in inner
    return func(*args, **kwargs)
  File "/home/ymane/.local/lib/python3.8/site-packages/django/db/backends/base/base.py", line 197, in connect
    self.connection = self.get_new_connection(conn_params)
  File "/home/ymane/.local/lib/python3.8/site-packages/django/utils/asyncio.py", line 26, in inner
    return func(*args, **kwargs)
  File "/home/ymane/.local/lib/python3.8/site-packages/django/db/backends/sqlite3/base.py", line 199, in get_new_connection
    conn = Database.connect(**conn_params)
django.db.utils.OperationalError: unable to open database file
[ ERROR ][ 2022-05-24 21:18:31,212 ][ log ][ 3880 ][ 140302757132032 ] ==> Internal Server Error: /session_security/ping/
Traceback (most recent call last):
  File "/home/ymane/.local/lib/python3.8/site-packages/django/contrib/sessions/backends/base.py", line 199, in _get_session
    return self._session_cache
AttributeError: 'SessionStore' object has no attribute '_session_cache'

During handling of the above exception, another exception occurred:

Traceback (most recent call last):
  File "/home/ymane/.local/lib/python3.8/site-packages/django/db/backends/base/base.py", line 220, in ensure_connection
    self.connect()
  File "/home/ymane/.local/lib/python3.8/site-packages/django/utils/asyncio.py", line 26, in inner
    return func(*args, **kwargs)
  File "/home/ymane/.local/lib/python3.8/site-packages/django/db/backends/base/base.py", line 197, in connect
    self.connection = self.get_new_connection(conn_params)
  File "/home/ymane/.local/lib/python3.8/site-packages/django/utils/asyncio.py", line 26, in inner
    return func(*args, **kwargs)
  File "/home/ymane/.local/lib/python3.8/site-packages/django/db/backends/sqlite3/base.py", line 199, in get_new_connection
    conn = Database.connect(**conn_params)
sqlite3.OperationalError: unable to open database file

The above exception was the direct cause of the following exception:

Traceback (most recent call last):
  File "/home/ymane/.local/lib/python3.8/site-packages/django/core/handlers/exception.py", line 34, in inner
    response = get_response(request)
  File "/home/ymane/.local/lib/python3.8/site-packages/django/utils/deprecation.py", line 96, in __call__
    response = self.process_response(request, response)
  File "/home/ymane/.local/lib/python3.8/site-packages/django/contrib/sessions/middleware.py", line 47, in process_response
    if request.session.get_expire_at_browser_close():
  File "/home/ymane/.local/lib/python3.8/site-packages/django/contrib/sessions/backends/base.py", line 291, in get_expire_at_browser_close
    if self.get('_session_expiry') is None:
  File "/home/ymane/.local/lib/python3.8/site-packages/django/contrib/sessions/backends/base.py", line 75, in get
    return self._session.get(key, default)
  File "/home/ymane/.local/lib/python3.8/site-packages/django/contrib/sessions/backends/base.py", line 204, in _get_session
    self._session_cache = self.load()
  File "/home/ymane/.local/lib/python3.8/site-packages/django/contrib/sessions/backends/db.py", line 43, in load
    s = self._get_session_from_db()
  File "/home/ymane/.local/lib/python3.8/site-packages/django/contrib/sessions/backends/db.py", line 32, in _get_session_from_db
    return self.model.objects.get(
  File "/home/ymane/.local/lib/python3.8/site-packages/django/db/models/manager.py", line 82, in manager_method
    return getattr(self.get_queryset(), name)(*args, **kwargs)
  File "/home/ymane/.local/lib/python3.8/site-packages/django/db/models/query.py", line 411, in get
    num = len(clone)
  File "/home/ymane/.local/lib/python3.8/site-packages/django/db/models/query.py", line 258, in __len__
    self._fetch_all()
  File "/home/ymane/.local/lib/python3.8/site-packages/django/db/models/query.py", line 1261, in _fetch_all
    self._result_cache = list(self._iterable_class(self))
  File "/home/ymane/.local/lib/python3.8/site-packages/django/db/models/query.py", line 57, in __iter__
    results = compiler.execute_sql(chunked_fetch=self.chunked_fetch, chunk_size=self.chunk_size)
  File "/home/ymane/.local/lib/python3.8/site-packages/django/db/models/sql/compiler.py", line 1150, in execute_sql
    cursor = self.connection.cursor()
  File "/home/ymane/.local/lib/python3.8/site-packages/django/utils/asyncio.py", line 26, in inner
    return func(*args, **kwargs)
  File "/home/ymane/.local/lib/python3.8/site-packages/django/db/backends/base/base.py", line 260, in cursor
    return self._cursor()
  File "/home/ymane/.local/lib/python3.8/site-packages/django/db/backends/base/base.py", line 236, in _cursor
    self.ensure_connection()
  File "/home/ymane/.local/lib/python3.8/site-packages/django/utils/asyncio.py", line 26, in inner
    return func(*args, **kwargs)
  File "/home/ymane/.local/lib/python3.8/site-packages/django/db/backends/base/base.py", line 220, in ensure_connection
    self.connect()
  File "/home/ymane/.local/lib/python3.8/site-packages/django/db/utils.py", line 90, in __exit__
    raise dj_exc_value.with_traceback(traceback) from exc_value
  File "/home/ymane/.local/lib/python3.8/site-packages/django/db/backends/base/base.py", line 220, in ensure_connection
    self.connect()
  File "/home/ymane/.local/lib/python3.8/site-packages/django/utils/asyncio.py", line 26, in inner
    return func(*args, **kwargs)
  File "/home/ymane/.local/lib/python3.8/site-packages/django/db/backends/base/base.py", line 197, in connect
    self.connection = self.get_new_connection(conn_params)
  File "/home/ymane/.local/lib/python3.8/site-packages/django/utils/asyncio.py", line 26, in inner
    return func(*args, **kwargs)
  File "/home/ymane/.local/lib/python3.8/site-packages/django/db/backends/sqlite3/base.py", line 199, in get_new_connection
    conn = Database.connect(**conn_params)
django.db.utils.OperationalError: unable to open database file
[ ERROR ][ 2022-05-24 21:18:31,235 ][ basehttp ][ 3880 ][ 140302757132032 ] ==> "GET /session_security/ping/?idleFor=80&_=1653425814847 HTTP/1.1" 500 28701
[ ERROR ][ 2022-05-24 21:23:41,115 ][ log ][ 3880 ][ 140302838060800 ] ==> Internal Server Error: /back-office/dashboard
Traceback (most recent call last):
  File "/home/ymane/.local/lib/python3.8/site-packages/django/contrib/sessions/backends/base.py", line 199, in _get_session
    return self._session_cache
AttributeError: 'SessionStore' object has no attribute '_session_cache'

During handling of the above exception, another exception occurred:

Traceback (most recent call last):
  File "/home/ymane/.local/lib/python3.8/site-packages/django/db/backends/base/base.py", line 220, in ensure_connection
    self.connect()
  File "/home/ymane/.local/lib/python3.8/site-packages/django/utils/asyncio.py", line 26, in inner
    return func(*args, **kwargs)
  File "/home/ymane/.local/lib/python3.8/site-packages/django/db/backends/base/base.py", line 197, in connect
    self.connection = self.get_new_connection(conn_params)
  File "/home/ymane/.local/lib/python3.8/site-packages/django/utils/asyncio.py", line 26, in inner
    return func(*args, **kwargs)
  File "/home/ymane/.local/lib/python3.8/site-packages/django/db/backends/sqlite3/base.py", line 199, in get_new_connection
    conn = Database.connect(**conn_params)
sqlite3.OperationalError: unable to open database file

The above exception was the direct cause of the following exception:

Traceback (most recent call last):
  File "/home/ymane/.local/lib/python3.8/site-packages/django/core/handlers/exception.py", line 34, in inner
    response = get_response(request)
  File "/home/ymane/.local/lib/python3.8/site-packages/django/utils/deprecation.py", line 93, in __call__
    response = self.process_request(request)
  File "/home/ymane/Téléchargements/EASYTRANS/session_security/middleware.py", line 62, in process_request
  File "/home/ymane/.local/lib/python3.8/site-packages/django/utils/functional.py", line 224, in inner
    self._setup()
  File "/home/ymane/.local/lib/python3.8/site-packages/django/utils/functional.py", line 360, in _setup
    self._wrapped = self._setupfunc()
  File "/home/ymane/.local/lib/python3.8/site-packages/django/contrib/auth/middleware.py", line 24, in <lambda>
    request.user = SimpleLazyObject(lambda: get_user(request))
  File "/home/ymane/.local/lib/python3.8/site-packages/django/contrib/auth/middleware.py", line 12, in get_user
    request._cached_user = auth.get_user(request)
  File "/home/ymane/.local/lib/python3.8/site-packages/django/contrib/auth/__init__.py", line 173, in get_user
    user_id = _get_user_session_key(request)
  File "/home/ymane/.local/lib/python3.8/site-packages/django/contrib/auth/__init__.py", line 58, in _get_user_session_key
    return get_user_model()._meta.pk.to_python(request.session[SESSION_KEY])
  File "/home/ymane/.local/lib/python3.8/site-packages/django/contrib/sessions/backends/base.py", line 64, in __getitem__
    return self._session[key]
  File "/home/ymane/.local/lib/python3.8/site-packages/django/contrib/sessions/backends/base.py", line 204, in _get_session
    self._session_cache = self.load()
  File "/home/ymane/.local/lib/python3.8/site-packages/django/contrib/sessions/backends/db.py", line 43, in load
    s = self._get_session_from_db()
  File "/home/ymane/.local/lib/python3.8/site-packages/django/contrib/sessions/backends/db.py", line 32, in _get_session_from_db
    return self.model.objects.get(
  File "/home/ymane/.local/lib/python3.8/site-packages/django/db/models/manager.py", line 82, in manager_method
    return getattr(self.get_queryset(), name)(*args, **kwargs)
  File "/home/ymane/.local/lib/python3.8/site-packages/django/db/models/query.py", line 411, in get
    num = len(clone)
  File "/home/ymane/.local/lib/python3.8/site-packages/django/db/models/query.py", line 258, in __len__
    self._fetch_all()
  File "/home/ymane/.local/lib/python3.8/site-packages/django/db/models/query.py", line 1261, in _fetch_all
    self._result_cache = list(self._iterable_class(self))
  File "/home/ymane/.local/lib/python3.8/site-packages/django/db/models/query.py", line 57, in __iter__
    results = compiler.execute_sql(chunked_fetch=self.chunked_fetch, chunk_size=self.chunk_size)
  File "/home/ymane/.local/lib/python3.8/site-packages/django/db/models/sql/compiler.py", line 1150, in execute_sql
    cursor = self.connection.cursor()
  File "/home/ymane/.local/lib/python3.8/site-packages/django/utils/asyncio.py", line 26, in inner
    return func(*args, **kwargs)
  File "/home/ymane/.local/lib/python3.8/site-packages/django/db/backends/base/base.py", line 260, in cursor
    return self._cursor()
  File "/home/ymane/.local/lib/python3.8/site-packages/django/db/backends/base/base.py", line 236, in _cursor
    self.ensure_connection()
  File "/home/ymane/.local/lib/python3.8/site-packages/django/utils/asyncio.py", line 26, in inner
    return func(*args, **kwargs)
  File "/home/ymane/.local/lib/python3.8/site-packages/django/db/backends/base/base.py", line 220, in ensure_connection
    self.connect()
  File "/home/ymane/.local/lib/python3.8/site-packages/django/db/utils.py", line 90, in __exit__
    raise dj_exc_value.with_traceback(traceback) from exc_value
  File "/home/ymane/.local/lib/python3.8/site-packages/django/db/backends/base/base.py", line 220, in ensure_connection
    self.connect()
  File "/home/ymane/.local/lib/python3.8/site-packages/django/utils/asyncio.py", line 26, in inner
    return func(*args, **kwargs)
  File "/home/ymane/.local/lib/python3.8/site-packages/django/db/backends/base/base.py", line 197, in connect
    self.connection = self.get_new_connection(conn_params)
  File "/home/ymane/.local/lib/python3.8/site-packages/django/utils/asyncio.py", line 26, in inner
    return func(*args, **kwargs)
  File "/home/ymane/.local/lib/python3.8/site-packages/django/db/backends/sqlite3/base.py", line 199, in get_new_connection
    conn = Database.connect(**conn_params)
django.db.utils.OperationalError: unable to open database file
[ ERROR ][ 2022-05-24 21:23:41,234 ][ log ][ 3880 ][ 140302838060800 ] ==> Internal Server Error: /back-office/dashboard
Traceback (most recent call last):
  File "/home/ymane/.local/lib/python3.8/site-packages/django/contrib/sessions/backends/base.py", line 199, in _get_session
    return self._session_cache
AttributeError: 'SessionStore' object has no attribute '_session_cache'

During handling of the above exception, another exception occurred:

Traceback (most recent call last):
  File "/home/ymane/.local/lib/python3.8/site-packages/django/db/backends/base/base.py", line 220, in ensure_connection
    self.connect()
  File "/home/ymane/.local/lib/python3.8/site-packages/django/utils/asyncio.py", line 26, in inner
    return func(*args, **kwargs)
  File "/home/ymane/.local/lib/python3.8/site-packages/django/db/backends/base/base.py", line 197, in connect
    self.connection = self.get_new_connection(conn_params)
  File "/home/ymane/.local/lib/python3.8/site-packages/django/utils/asyncio.py", line 26, in inner
    return func(*args, **kwargs)
  File "/home/ymane/.local/lib/python3.8/site-packages/django/db/backends/sqlite3/base.py", line 199, in get_new_connection
    conn = Database.connect(**conn_params)
sqlite3.OperationalError: unable to open database file

The above exception was the direct cause of the following exception:

Traceback (most recent call last):
  File "/home/ymane/.local/lib/python3.8/site-packages/django/core/handlers/exception.py", line 34, in inner
    response = get_response(request)
  File "/home/ymane/.local/lib/python3.8/site-packages/django/utils/deprecation.py", line 96, in __call__
    response = self.process_response(request, response)
  File "/home/ymane/Téléchargements/EASYTRANS/request/middleware.py", line 36, in process_response
  File "/home/ymane/.local/lib/python3.8/site-packages/django/utils/functional.py", line 224, in inner
    self._setup()
  File "/home/ymane/.local/lib/python3.8/site-packages/django/utils/functional.py", line 360, in _setup
    self._wrapped = self._setupfunc()
  File "/home/ymane/.local/lib/python3.8/site-packages/django/contrib/auth/middleware.py", line 24, in <lambda>
    request.user = SimpleLazyObject(lambda: get_user(request))
  File "/home/ymane/.local/lib/python3.8/site-packages/django/contrib/auth/middleware.py", line 12, in get_user
    request._cached_user = auth.get_user(request)
  File "/home/ymane/.local/lib/python3.8/site-packages/django/contrib/auth/__init__.py", line 173, in get_user
    user_id = _get_user_session_key(request)
  File "/home/ymane/.local/lib/python3.8/site-packages/django/contrib/auth/__init__.py", line 58, in _get_user_session_key
    return get_user_model()._meta.pk.to_python(request.session[SESSION_KEY])
  File "/home/ymane/.local/lib/python3.8/site-packages/django/contrib/sessions/backends/base.py", line 64, in __getitem__
    return self._session[key]
  File "/home/ymane/.local/lib/python3.8/site-packages/django/contrib/sessions/backends/base.py", line 204, in _get_session
    self._session_cache = self.load()
  File "/home/ymane/.local/lib/python3.8/site-packages/django/contrib/sessions/backends/db.py", line 43, in load
    s = self._get_session_from_db()
  File "/home/ymane/.local/lib/python3.8/site-packages/django/contrib/sessions/backends/db.py", line 32, in _get_session_from_db
    return self.model.objects.get(
  File "/home/ymane/.local/lib/python3.8/site-packages/django/db/models/manager.py", line 82, in manager_method
    return getattr(self.get_queryset(), name)(*args, **kwargs)
  File "/home/ymane/.local/lib/python3.8/site-packages/django/db/models/query.py", line 411, in get
    num = len(clone)
  File "/home/ymane/.local/lib/python3.8/site-packages/django/db/models/query.py", line 258, in __len__
    self._fetch_all()
  File "/home/ymane/.local/lib/python3.8/site-packages/django/db/models/query.py", line 1261, in _fetch_all
    self._result_cache = list(self._iterable_class(self))
  File "/home/ymane/.local/lib/python3.8/site-packages/django/db/models/query.py", line 57, in __iter__
    results = compiler.execute_sql(chunked_fetch=self.chunked_fetch, chunk_size=self.chunk_size)
  File "/home/ymane/.local/lib/python3.8/site-packages/django/db/models/sql/compiler.py", line 1150, in execute_sql
    cursor = self.connection.cursor()
  File "/home/ymane/.local/lib/python3.8/site-packages/django/utils/asyncio.py", line 26, in inner
    return func(*args, **kwargs)
  File "/home/ymane/.local/lib/python3.8/site-packages/django/db/backends/base/base.py", line 260, in cursor
    return self._cursor()
  File "/home/ymane/.local/lib/python3.8/site-packages/django/db/backends/base/base.py", line 236, in _cursor
    self.ensure_connection()
  File "/home/ymane/.local/lib/python3.8/site-packages/django/utils/asyncio.py", line 26, in inner
    return func(*args, **kwargs)
  File "/home/ymane/.local/lib/python3.8/site-packages/django/db/backends/base/base.py", line 220, in ensure_connection
    self.connect()
  File "/home/ymane/.local/lib/python3.8/site-packages/django/db/utils.py", line 90, in __exit__
    raise dj_exc_value.with_traceback(traceback) from exc_value
  File "/home/ymane/.local/lib/python3.8/site-packages/django/db/backends/base/base.py", line 220, in ensure_connection
    self.connect()
  File "/home/ymane/.local/lib/python3.8/site-packages/django/utils/asyncio.py", line 26, in inner
    return func(*args, **kwargs)
  File "/home/ymane/.local/lib/python3.8/site-packages/django/db/backends/base/base.py", line 197, in connect
    self.connection = self.get_new_connection(conn_params)
  File "/home/ymane/.local/lib/python3.8/site-packages/django/utils/asyncio.py", line 26, in inner
    return func(*args, **kwargs)
  File "/home/ymane/.local/lib/python3.8/site-packages/django/db/backends/sqlite3/base.py", line 199, in get_new_connection
    conn = Database.connect(**conn_params)
django.db.utils.OperationalError: unable to open database file
[ ERROR ][ 2022-05-24 21:23:41,334 ][ log ][ 3880 ][ 140302838060800 ] ==> Internal Server Error: /back-office/dashboard
Traceback (most recent call last):
  File "/home/ymane/.local/lib/python3.8/site-packages/django/contrib/sessions/backends/base.py", line 199, in _get_session
    return self._session_cache
AttributeError: 'SessionStore' object has no attribute '_session_cache'

During handling of the above exception, another exception occurred:

Traceback (most recent call last):
  File "/home/ymane/.local/lib/python3.8/site-packages/django/db/backends/base/base.py", line 220, in ensure_connection
    self.connect()
  File "/home/ymane/.local/lib/python3.8/site-packages/django/utils/asyncio.py", line 26, in inner
    return func(*args, **kwargs)
  File "/home/ymane/.local/lib/python3.8/site-packages/django/db/backends/base/base.py", line 197, in connect
    self.connection = self.get_new_connection(conn_params)
  File "/home/ymane/.local/lib/python3.8/site-packages/django/utils/asyncio.py", line 26, in inner
    return func(*args, **kwargs)
  File "/home/ymane/.local/lib/python3.8/site-packages/django/db/backends/sqlite3/base.py", line 199, in get_new_connection
    conn = Database.connect(**conn_params)
sqlite3.OperationalError: unable to open database file

The above exception was the direct cause of the following exception:

Traceback (most recent call last):
  File "/home/ymane/.local/lib/python3.8/site-packages/django/core/handlers/exception.py", line 34, in inner
    response = get_response(request)
  File "/home/ymane/.local/lib/python3.8/site-packages/django/utils/deprecation.py", line 96, in __call__
    response = self.process_response(request, response)
  File "/home/ymane/.local/lib/python3.8/site-packages/django/contrib/sessions/middleware.py", line 47, in process_response
    if request.session.get_expire_at_browser_close():
  File "/home/ymane/.local/lib/python3.8/site-packages/django/contrib/sessions/backends/base.py", line 291, in get_expire_at_browser_close
    if self.get('_session_expiry') is None:
  File "/home/ymane/.local/lib/python3.8/site-packages/django/contrib/sessions/backends/base.py", line 75, in get
    return self._session.get(key, default)
  File "/home/ymane/.local/lib/python3.8/site-packages/django/contrib/sessions/backends/base.py", line 204, in _get_session
    self._session_cache = self.load()
  File "/home/ymane/.local/lib/python3.8/site-packages/django/contrib/sessions/backends/db.py", line 43, in load
    s = self._get_session_from_db()
  File "/home/ymane/.local/lib/python3.8/site-packages/django/contrib/sessions/backends/db.py", line 32, in _get_session_from_db
    return self.model.objects.get(
  File "/home/ymane/.local/lib/python3.8/site-packages/django/db/models/manager.py", line 82, in manager_method
    return getattr(self.get_queryset(), name)(*args, **kwargs)
  File "/home/ymane/.local/lib/python3.8/site-packages/django/db/models/query.py", line 411, in get
    num = len(clone)
  File "/home/ymane/.local/lib/python3.8/site-packages/django/db/models/query.py", line 258, in __len__
    self._fetch_all()
  File "/home/ymane/.local/lib/python3.8/site-packages/django/db/models/query.py", line 1261, in _fetch_all
    self._result_cache = list(self._iterable_class(self))
  File "/home/ymane/.local/lib/python3.8/site-packages/django/db/models/query.py", line 57, in __iter__
    results = compiler.execute_sql(chunked_fetch=self.chunked_fetch, chunk_size=self.chunk_size)
  File "/home/ymane/.local/lib/python3.8/site-packages/django/db/models/sql/compiler.py", line 1150, in execute_sql
    cursor = self.connection.cursor()
  File "/home/ymane/.local/lib/python3.8/site-packages/django/utils/asyncio.py", line 26, in inner
    return func(*args, **kwargs)
  File "/home/ymane/.local/lib/python3.8/site-packages/django/db/backends/base/base.py", line 260, in cursor
    return self._cursor()
  File "/home/ymane/.local/lib/python3.8/site-packages/django/db/backends/base/base.py", line 236, in _cursor
    self.ensure_connection()
  File "/home/ymane/.local/lib/python3.8/site-packages/django/utils/asyncio.py", line 26, in inner
    return func(*args, **kwargs)
  File "/home/ymane/.local/lib/python3.8/site-packages/django/db/backends/base/base.py", line 220, in ensure_connection
    self.connect()
  File "/home/ymane/.local/lib/python3.8/site-packages/django/db/utils.py", line 90, in __exit__
    raise dj_exc_value.with_traceback(traceback) from exc_value
  File "/home/ymane/.local/lib/python3.8/site-packages/django/db/backends/base/base.py", line 220, in ensure_connection
    self.connect()
  File "/home/ymane/.local/lib/python3.8/site-packages/django/utils/asyncio.py", line 26, in inner
    return func(*args, **kwargs)
  File "/home/ymane/.local/lib/python3.8/site-packages/django/db/backends/base/base.py", line 197, in connect
    self.connection = self.get_new_connection(conn_params)
  File "/home/ymane/.local/lib/python3.8/site-packages/django/utils/asyncio.py", line 26, in inner
    return func(*args, **kwargs)
  File "/home/ymane/.local/lib/python3.8/site-packages/django/db/backends/sqlite3/base.py", line 199, in get_new_connection
    conn = Database.connect(**conn_params)
django.db.utils.OperationalError: unable to open database file
[ ERROR ][ 2022-05-24 21:23:41,360 ][ basehttp ][ 3880 ][ 140302838060800 ] ==> "GET /back-office/dashboard HTTP/1.1" 500 201698
[ INFO ][ 2022-05-24 21:28:57,515 ][ autoreload ][ 6723 ][ 139771183486784 ] ==> Watching for file changes with StatReloader
[ INFO ][ 2022-05-24 21:29:53,843 ][ basehttp ][ 6723 ][ 139770978641664 ] ==> "GET /back-office/dashboard HTTP/1.1" 302 0
[ INFO ][ 2022-05-24 21:29:54,097 ][ basehttp ][ 6723 ][ 139770978641664 ] ==> "GET /back-office/login/ HTTP/1.1" 200 2418
[ INFO ][ 2022-05-24 21:29:58,745 ][ basehttp ][ 6723 ][ 139770978641664 ] ==> "POST /back-office/login/ HTTP/1.1" 302 0
[ INFO ][ 2022-05-24 21:29:59,770 ][ basehttp ][ 6723 ][ 139770978641664 ] ==> "GET /back-office/dashboard HTTP/1.1" 200 172067
[ WARNING ][ 2022-05-24 21:30:02,560 ][ basehttp ][ 6723 ][ 139770970248960 ] ==> "GET /static/website/back/fonts/materialdesignicons-webfont.woff2%3Fv=1.6.50 HTTP/1.1" 404 1914
[ WARNING ][ 2022-05-24 21:30:02,561 ][ basehttp ][ 6723 ][ 139770978641664 ] ==> "GET /static/website/back/fonts/fontawesome-webfont.woff2%3Fv=4.6.3 HTTP/1.1" 404 1887
[ WARNING ][ 2022-05-24 21:30:02,669 ][ basehttp ][ 6723 ][ 139770978641664 ] ==> "GET /static/website/back/fonts/fontawesome-webfont.woff%3Fv=4.6.3 HTTP/1.1" 404 1884
[ WARNING ][ 2022-05-24 21:30:02,732 ][ basehttp ][ 6723 ][ 139770978641664 ] ==> "GET /static/website/back/fonts/materialdesignicons-webfont.woff%3Fv=1.6.50 HTTP/1.1" 404 1911
[ WARNING ][ 2022-05-24 21:30:02,733 ][ basehttp ][ 6723 ][ 139770970248960 ] ==> "GET /static/website/back/fonts/fontawesome-webfont.ttf%3Fv=4.6.3 HTTP/1.1" 404 1881
[ WARNING ][ 2022-05-24 21:30:02,768 ][ basehttp ][ 6723 ][ 139770970248960 ] ==> "GET /static/website/back/fonts/materialdesignicons-webfont.ttf%3Fv=1.6.50 HTTP/1.1" 404 1908
[ INFO ][ 2022-05-24 21:30:22,634 ][ autoreload ][ 6723 ][ 139771183486784 ] ==> /home/ymane/Téléchargements/EASYTRANS/start_form/models.py changed, reloading.
[ INFO ][ 2022-05-24 21:30:24,272 ][ autoreload ][ 6859 ][ 140229819156288 ] ==> Watching for file changes with StatReloader
[ INFO ][ 2022-05-24 21:30:27,654 ][ autoreload ][ 6859 ][ 140229819156288 ] ==> /home/ymane/Téléchargements/EASYTRANS/start_form/models.py changed, reloading.
[ INFO ][ 2022-05-24 21:30:28,185 ][ autoreload ][ 6884 ][ 139662090516288 ] ==> Watching for file changes with StatReloader
[ INFO ][ 2022-05-24 21:30:45,640 ][ autoreload ][ 6884 ][ 139662090516288 ] ==> /home/ymane/Téléchargements/EASYTRANS/start_form/models.py changed, reloading.
[ INFO ][ 2022-05-24 21:30:46,597 ][ autoreload ][ 6913 ][ 139686987265856 ] ==> Watching for file changes with StatReloader
[ INFO ][ 2022-05-24 21:31:03,553 ][ autoreload ][ 6973 ][ 140614691329856 ] ==> Watching for file changes with StatReloader
[ INFO ][ 2022-05-24 21:31:07,016 ][ basehttp ][ 6973 ][ 140614486181632 ] ==> "GET /back-office/dashboard HTTP/1.1" 200 172067
[ WARNING ][ 2022-05-24 21:31:07,158 ][ basehttp ][ 6973 ][ 140614486181632 ] ==> "GET /static/website/back/fonts/materialdesignicons-webfont.woff2%3Fv=1.6.50 HTTP/1.1" 404 1914
[ WARNING ][ 2022-05-24 21:31:07,159 ][ basehttp ][ 6973 ][ 140614477788928 ] ==> "GET /static/website/back/fonts/fontawesome-webfont.woff2%3Fv=4.6.3 HTTP/1.1" 404 1887
[ WARNING ][ 2022-05-24 21:31:07,324 ][ basehttp ][ 6973 ][ 140614477788928 ] ==> "GET /static/website/back/fonts/materialdesignicons-webfont.woff%3Fv=1.6.50 HTTP/1.1" 404 1911
[ WARNING ][ 2022-05-24 21:31:07,324 ][ basehttp ][ 6973 ][ 140614486181632 ] ==> "GET /static/website/back/fonts/fontawesome-webfont.woff%3Fv=4.6.3 HTTP/1.1" 404 1884
[ WARNING ][ 2022-05-24 21:31:07,339 ][ basehttp ][ 6973 ][ 140614486181632 ] ==> "GET /static/website/back/fonts/materialdesignicons-webfont.ttf%3Fv=1.6.50 HTTP/1.1" 404 1908
[ WARNING ][ 2022-05-24 21:31:07,370 ][ basehttp ][ 6973 ][ 140614486181632 ] ==> "GET /static/website/back/fonts/fontawesome-webfont.ttf%3Fv=4.6.3 HTTP/1.1" 404 1881
[ INFO ][ 2022-05-24 21:31:15,316 ][ basehttp ][ 6973 ][ 140614486181632 ] ==> "GET /admin-back-office/ HTTP/1.1" 200 18361
[ INFO ][ 2022-05-24 21:31:16,744 ][ basehttp ][ 6973 ][ 140614477788928 ] ==> "GET /static/admin/fonts/Roboto-Bold-webfont.woff HTTP/1.1" 200 82564
[ INFO ][ 2022-05-24 21:31:16,748 ][ basehttp ][ 6973 ][ 140614486181632 ] ==> "GET /static/admin/fonts/Roboto-Light-webfont.woff HTTP/1.1" 200 81348
[ INFO ][ 2022-05-24 21:31:16,753 ][ basehttp ][ 6973 ][ 140614466512640 ] ==> "GET /static/admin/fonts/Roboto-Regular-webfont.woff HTTP/1.1" 200 80304
[ INFO ][ 2022-05-24 21:33:05,055 ][ basehttp ][ 6973 ][ 140614466512640 ] ==> "GET /admin-back-office/start_form/voyage/ HTTP/1.1" 200 12281
[ INFO ][ 2022-05-24 21:33:05,147 ][ basehttp ][ 6973 ][ 140614466512640 ] ==> "GET /static/admin/js/vendor/jquery/jquery.js HTTP/1.1" 200 271751
[ INFO ][ 2022-05-24 21:33:05,157 ][ basehttp ][ 6973 ][ 140614477788928 ] ==> "GET /static/admin/js/vendor/xregexp/xregexp.js HTTP/1.1" 200 128820
[ INFO ][ 2022-05-24 21:33:05,739 ][ basehttp ][ 6973 ][ 140614486181632 ] ==> "GET /admin-back-office/jsi18n/ HTTP/1.1" 200 7403
[ INFO ][ 2022-05-24 21:33:10,312 ][ basehttp ][ 6973 ][ 140614486181632 ] ==> "GET /admin-back-office/start_form/voyage/34/change/ HTTP/1.1" 200 12582
[ INFO ][ 2022-05-24 21:33:10,733 ][ basehttp ][ 6973 ][ 140614486181632 ] ==> "GET /admin-back-office/jsi18n/ HTTP/1.1" 200 7403
[ INFO ][ 2022-05-24 21:38:34,880 ][ basehttp ][ 6973 ][ 140614486181632 ] ==> "POST /admin-back-office/start_form/voyage/34/change/ HTTP/1.1" 302 0
[ INFO ][ 2022-05-24 21:38:36,581 ][ basehttp ][ 6973 ][ 140614486181632 ] ==> "GET /admin-back-office/start_form/voyage/ HTTP/1.1" 200 12497
[ INFO ][ 2022-05-24 21:38:38,496 ][ basehttp ][ 6973 ][ 140614486181632 ] ==> "GET /admin-back-office/jsi18n/ HTTP/1.1" 200 7403
[ INFO ][ 2022-05-24 21:38:41,665 ][ basehttp ][ 6973 ][ 140614486181632 ] ==> "GET /admin-back-office/start_form/voyage/33/change/ HTTP/1.1" 200 12581
[ INFO ][ 2022-05-24 21:38:41,920 ][ basehttp ][ 6973 ][ 140614486181632 ] ==> "GET /admin-back-office/jsi18n/ HTTP/1.1" 200 7403
[ INFO ][ 2022-05-24 21:38:52,890 ][ basehttp ][ 6973 ][ 140614486181632 ] ==> "POST /admin-back-office/start_form/voyage/33/change/ HTTP/1.1" 302 0
[ INFO ][ 2022-05-24 21:38:53,234 ][ basehttp ][ 6973 ][ 140614486181632 ] ==> "GET /admin-back-office/start_form/voyage/ HTTP/1.1" 200 12497
[ INFO ][ 2022-05-24 21:38:53,650 ][ basehttp ][ 6973 ][ 140614486181632 ] ==> "GET /admin-back-office/jsi18n/ HTTP/1.1" 200 7403
[ INFO ][ 2022-05-24 21:38:58,251 ][ basehttp ][ 6973 ][ 140614486181632 ] ==> "GET /admin-back-office/start_form/voyage/27/change/ HTTP/1.1" 200 12587
[ INFO ][ 2022-05-24 21:38:58,528 ][ basehttp ][ 6973 ][ 140614486181632 ] ==> "GET /admin-back-office/jsi18n/ HTTP/1.1" 200 7403
[ INFO ][ 2022-05-24 21:39:07,329 ][ basehttp ][ 6973 ][ 140614486181632 ] ==> "POST /admin-back-office/start_form/voyage/27/change/ HTTP/1.1" 302 0
[ INFO ][ 2022-05-24 21:39:07,659 ][ basehttp ][ 6973 ][ 140614486181632 ] ==> "GET /admin-back-office/start_form/voyage/ HTTP/1.1" 200 12500
[ INFO ][ 2022-05-24 21:39:07,837 ][ basehttp ][ 6973 ][ 140614486181632 ] ==> "GET /admin-back-office/jsi18n/ HTTP/1.1" 200 7403
[ INFO ][ 2022-05-24 21:45:09,824 ][ basehttp ][ 6973 ][ 140614486181632 ] ==> "GET /session_security/ping/?idleFor=32&_=1653427867171 HTTP/1.1" 200 2
[ INFO ][ 2022-05-24 21:56:17,500 ][ basehttp ][ 6973 ][ 140614486181632 ] ==> "GET /back-office/traitement/4 HTTP/1.1" 200 840
[ INFO ][ 2022-05-24 21:56:22,300 ][ basehttp ][ 6973 ][ 140614486181632 ] ==> "GET /back-office/dashboard HTTP/1.1" 200 172067
[ WARNING ][ 2022-05-24 21:56:22,701 ][ basehttp ][ 6973 ][ 140614486181632 ] ==> "GET /static/website/back/fonts/materialdesignicons-webfont.woff2%3Fv=1.6.50 HTTP/1.1" 404 1914
[ WARNING ][ 2022-05-24 21:56:22,705 ][ basehttp ][ 6973 ][ 140614477788928 ] ==> "GET /static/website/back/fonts/fontawesome-webfont.woff2%3Fv=4.6.3 HTTP/1.1" 404 1887
[ WARNING ][ 2022-05-24 21:56:22,829 ][ basehttp ][ 6973 ][ 140614477788928 ] ==> "GET /static/website/back/fonts/materialdesignicons-webfont.woff%3Fv=1.6.50 HTTP/1.1" 404 1911
[ WARNING ][ 2022-05-24 21:56:22,836 ][ basehttp ][ 6973 ][ 140614486181632 ] ==> "GET /static/website/back/fonts/fontawesome-webfont.woff%3Fv=4.6.3 HTTP/1.1" 404 1884
[ WARNING ][ 2022-05-24 21:56:23,221 ][ basehttp ][ 6973 ][ 140614486181632 ] ==> "GET /static/website/back/fonts/materialdesignicons-webfont.ttf%3Fv=1.6.50 HTTP/1.1" 404 1908
[ WARNING ][ 2022-05-24 21:56:23,246 ][ basehttp ][ 6973 ][ 140614486181632 ] ==> "GET /static/website/back/fonts/fontawesome-webfont.ttf%3Fv=4.6.3 HTTP/1.1" 404 1881
[ INFO ][ 2022-05-24 22:10:25,290 ][ basehttp ][ 6973 ][ 140614486181632 ] ==> "GET /session_security/ping/?idleFor=226&_=1653429382585 HTTP/1.1" 200 3
[ INFO ][ 2022-05-24 22:20:42,456 ][ basehttp ][ 6973 ][ 140614486181632 ] ==> "GET /session_security/ping/?idleFor=316&_=1653429382586 HTTP/1.1" 200 3
